Workbook

Sheet Hinweise
A1: SCHLEIMTÜRME: Werte für alle Inspector-Felder
A2: Blaue Zahlen sind Eingabewerte, die 1:1 in die Unity-Felder gehören. Schwarze Zellen in 'Kumuliert' sind Formeln (Grundwert + alle Upgrades bis zum Level).
A3: Spaltenüberschriften sind die Feldnamen im Unity-Inspector. Anteile (Crit, Pen, Omnivamp, Multiplikatoren) sind Werte von 0 bis 1 (0.15 = 15 %).
A5: Aufbau
A6: Türme: Werte des Turm-Prefabs auf Level 1 (inkl. bonusPerLevel, das bei jedem Level-Up addiert wird).
A7: Upgrades: je Turm 3 Pfade mit 2 Stufen (Level 2 und 3). Pro Pfad wird nur einer gewählt. Werte sind Zuwächse, die auf den Turm addiert werden.
A8: Projektile: ein Prefab pro Variante. Das Projektil wechselt, wenn das Upgrade ein 'projectile' angibt. Alle Felder stehen drin, relevant sind nur die des gewählten 'mode'.
A9: Kumuliert: berechnet Schaden, Abklingzeit, DPS, Reichweite, HP und Defensiv-/Offensivwerte je Pfad und Level. Zum Balancieren.
A10: Achtung: Schaden und DPS in 'Kumuliert' zählen nur den Turmschaden (damage). Der Eigenschaden der Projektile (baseDmg, chainDamage, DoT-Ticks, splitterDamage, Sticky-/Link-Schaden) kommt on top, siehe 'Projektile'. Ohne diesen sind Quallen-, Säure- und Abflussturm in der Tabelle scheinbar schwach.
A12: Annahmen (bitte an dein Spiel anpassen)
A13: 1 Weltenheit = 1 Kachel. Reichweiten 5 bis 6,5 Kacheln. Preise, Forschungskosten und Schaden sind Startwerte ohne Kenntnis deiner Gegnerwerte.
A14: Schleimlinge, Abpraller und Slow-Werte sind Vorschläge. Die Gegner-Gesundheit entscheidet, ob 8 Schaden alle 1,6 s passt.
... A25: Leimfalle ist ein Support-Turm: seine Multiplikatoren (Reichweite, Schaden, Tempo, Slow) gelten für andere Türme in seiner Reichweite.

Sheet Türme
A1: Turm | B1: towerName | C1: towerDesc | D1: towerInitPrice | E1: displayedStats (Flags) | F1: displayedStats (Wert) | G1: statHealthPoints | H1: currentHealth | I1: baseArmor | J1: baseMagicResist | K1: autoAddVitals | L1: range | M1: interactionrange | N1: damage | O1: timeInBetweenShots | P1: attackSpeedMultiplier | Q1: targetPreference | R1: offense.critChance | S1: offense.critDamage | T1: offense.lethality | U1: offense.armorPenPercent | V1: offense.magicPenFlat | W1: offense.magicPenPercent | X1: offense.omnivamp | Y1: statCoinsEarnedPerSecond | Z1: statHealthRegenPerSecond | AA1: statRangeMultiplier | AB1: statDmgMultiplier | AC1: statAttackSpeedMultiplier | AD1: statSlowMultiplier | AE1: projectilePrefab | AF1: bonusPerLevel.health | AG1: bonusPerLevel.healthRegen | AH1: bonusPerLevel.damage | AI1: bonusPerLevel.range | AJ1: bonusPerLevel.cooldownDecrease | AK1: bonusPerLevel.armor | AL1: bonusPerLevel.magicResist | AM1: bonusPerLevel.critChance | AN1: bonusPerLevel.critDamage | AO1: bonusPerLevel.lethality | AP1: bonusPerLevel.armorPenPercent | AQ1: bonusPerLevel.magicPenFlat | AR1: bonusPerLevel.magicPenPercent | AS1: bonusPerLevel.omnivamp
A2: Glibberwerfer | B2: Glibberwerfer | C2: Schleudert zähe Klumpen, die abprallen und Gegner verlangsamen. Abpraller: 1 · Slow: 15 % (1,5 s) Schaden 8, alle 1,6 s, Reichweite 6, 110 HP, Rüstung 5 | D2: 8 | E2: Damage|Range|AttackSpeed|Health|Regen|Armor|MagicResist|CritChance|CritDamage|Penetration|Omnivamp | F2: 64559 | G2: 110 | H2: 110 | I2: 5 | J2: 0 | K2: ja | L2: 6 | M2: 1.5 | N2: 8 | O2: 1.6 | P2: 1 | Q2: Nearest | R2: 0 | S2: 1.75 | T2: 0 | U2: 0 | V2: 0 | W2: 0 | X2: 0 | Y2: 0 | Z2: 0 | AA2: 0 | AB2: 0 | AC2: 0 | AD2: 0 | AE2: P_Glibber_Basis | AF2: 8 | AG2: 0 | AH2: 1 | AI2: 0 | AJ2: 0 | AK2: 1 | AL2: 0 | AM2: 0.01 | AN2: 0 | AO2: 0 | AP2: 0 | AQ2: 0 | AR2: 0 | AS2: 0
A3: Säuretümpel | B3: Säuretümpel | C3: Spuckt ätzende Säure, die Gegner über Zeit zersetzt. Gift: 4 alle 0,5 s · Gift-Dauer: 3 s Schaden 5, alle 2,2 s, Reichweite 5,5, 100 HP, Magieresistenz 5 | D3: 10 | E3: Damage|Range|AttackSpeed|Health|MagicResist|Penetration | F3: 10255 | G3: 100 | H3: 100 | I3: 0 | J3: 5 | K3: ja | L3: 5.5 | M3: 1.5 | N3: 5 | O3: 2.2 | P3: 1 | Q3: Strongest | R3: 0 | S3: 1.75 | T3: 0 | U3: 0 | V3: 0 | W3: 0 | X3: 0 | Y3: 0 | Z3: 0 | AA3: 0 | AB3: 0 | AC3: 0 | AD3: 0 | AE3: P_Saeure_Basis | AF3: 8 | AG3: 0 | AH3: 1 | AI3: 0 | AJ3: 0 | AK3: 0 | AL3: 1 | AM3: 0 | AN3: 0 | AO3: 0 | AP3: 0 | AQ3: 0.5 | AR3: 0 | AS3: 0
A4: Spaltschleim | B4: Spaltschleim | C4: Klumpen, die beim Aufprall in kleine Schleimlinge zerplatzen. Splitter: 3 · Splitterschaden: 3 Schaden 8, alle 2 s, Reichweite 5,5, 110 HP, Rüstung 3, Magieresistenz 3 | D4: 12 | E4: Damage|Range|AttackSpeed|Health|Regen|Armor|MagicResist|CritChance|Penetration|Omnivamp | F4: 31791 | G4: 110 | H4: 110 | I4: 3 | J4: 3 | K4: ja | L4: 5.5 | M4: 1.5 | N4: 8 | O4: 2 | P4: 1 | Q4: First | R4: 0 | S4: 1.75 | T4: 0 | U4: 0 | V4: 0 | W4: 0 | X4: 0 | Y4: 0 | Z4: 0 | AA4: 0 | AB4: 0 | AC4: 0 | AD4: 0 | AE4: P_Spalt_Basis | AF4: 8 | AG4: 0 | AH4: 1 | AI4: 0 | AJ4: 0 | AK4: 0 | AL4: 0 | AM4: 0.01 | AN4: 0 | AO4: 0.5 | AP4: 0 | AQ4: 0 | AR4: 0 | AS4: 0
A5: Klebfadenturm | B5: Klebfadenturm | C5: Spannt klebrige Fäden zwischen Gegnern und verlangsamt sie. Fadenradius: 4 · Fadenslow: 40 % · Fadenschaden: 3 alle 0,5 s Schaden 6, alle 2,4 s, Reichweite 5, 120 HP, Rüstung 5, Magieresistenz 5 | D5: 12 | E5: Damage|Range|AttackSpeed|Health|Armor|MagicResist|Penetration|RangeMultiplier|DamageMultiplier|AttackSpeedMultiplier|SlowMultiplier | F5: 12239 | G5: 120 | H5: 120 | I5: 5 | J5: 5 | K5: ja | L5: 5 | M5: 1.5 | N5: 6 | O5: 2.4 | P5: 1 | Q5: Nearest | R5: 0 | S5: 1.75 | T5: 0 | U5: 0 | V5: 0 | W5: 0 | X5: 0 | Y5: 0 | Z5: 0 | AA5: 0 | AB5: 0 | AC5: 0 | AD5: 0 | AE5: P_Faden_Basis | AF5: 10 | AG5: 0 | AH5: 1 | AI5: 0 | AJ5: 0 | AK5: 1 | AL5: 1 | AM5: 0 | AN5: 0 | AO5: 0 | AP5: 0 | AQ5: 0 | AR5: 0 | AS5: 0
A6: Quallenturm | B6: Quallenturm | C6: Entlädt Blitze, die von Gegner zu Gegner springen. Blitzziele: 2 · Blitzschaden: 8 · Blitzradius: 3 · Blitzabfall: 20 % Schaden 4, alle 1,8 s, Reichweite 5,5, 100 HP, Magieresistenz 10 | D6: 14 | E6: Damage|Range|AttackSpeed|Health|Regen|Armor|MagicResist|CritChance|CritDamage|Penetration|Omnivamp | F6: 64559 | G6: 100 | H6: 100 | I6: 0 | J6: 10 | K6: ja | L6: 5.5 | M6: 1.5 | N6: 4 | O6: 1.8 | P6: 1 | Q6: First | R6: 0 | S6: 1.75 | T6: 0 | U6: 0 | V6: 0 | W6: 0 | X6: 0 | Y6: 0 | Z6: 0 | AA6: 0 | AB6: 0 | AC6: 0 | AD6: 0 | AE6: P_Qualle_Basis | AF6: 8 | AG6: 0 | AH6: 1 | AI6: 0 | AJ6: 0 | AK6: 0 | AL6: 1 | AM6: 0.01 | AN6: 0 | AO6: 0 | AP6: 0 | AQ6: 0 | AR6: 0 | AS6: 0
A7: Schleimabfluss | B7: Schleimabfluss | C7: Reißt Gegner in einen Schleimstrudel und zerquetscht sie. Sogdauer: 2 s · Sogradius: 3 Schaden 14, alle 5 s, Reichweite 6,5, 100 HP, Magieresistenz 10 | D7: 16 | E7: Damage|Range|AttackSpeed|Health|Regen|Armor|MagicResist|Penetration|Omnivamp | F7: 27695 | G7: 100 | H7: 100 | I7: 0 | J7: 10 | K7: ja | L7: 6.5 | M7: 1.5 | N7: 14 | O7: 5 | P7: 1 | Q7: Strongest | R7: 0 | S7: 1.75 | T7: 0 | U7: 0 | V7: 0 | W7: 0 | X7: 0 | Y7: 0 | Z7: 0 | AA7: 0 | AB7: 0 | AC7: 0 | AD7: 0 | AE7: P_Abfluss_Basis | AF7: 8 | AG7: 0 | AH7: 2 | AI7: 0 | AJ7: 0 | AK7: 0 | AL7: 1 | AM7: 0 | AN7: 0 | AO7: 0 | AP7: 0 | AQ7: 0.5 | AR7: 0 | AS7: 0

Sheet Upgrades
A1: Turm | B1: Pfad-Nr | C1: Pfad-Name (UpgradePath.towerName) | D1: Pfad-Forschung (UpgradePath.researchCost) | E1: Level | F1: upgradeName | G1: description | H1: researchCost | I1: upgradeCost | J1: damageIncrease | K1: rangeIncrease | L1: attackSpeedIncrease | M1: timeInBetweenShotsDecrease | N1: coinsEarnedPerSecond | O1: healthpoints | P1: healthRegenPerSecond | Q1: rangeMultiplier | R1: dmgMultiplier | S1: attackSpeedMultiplier | T1: slowMultiplier | U1: bonus.health | V1: bonus.healthRegen | W1: bonus.damage | X1: bonus.range | Y1: bonus.cooldownDecrease | Z1: bonus.armor | AA1: bonus.magicResist | AB1: bonus.critChance | AC1: bonus.critDamage | AD1: bonus.lethality | AE1: bonus.armorPenPercent | AF1: bonus.magicPenFlat | AG1: bonus.magicPenPercent | AH1: bonus.omnivamp | AI1: projectile
A2: Glibberwerfer | B2: 0 | C2: Glibberwerfer - Hüpfer | D2: 10 | E2: 2 | F2: Gummiball | G2: Abpraller: 1 → 3 +1 Schaden, +0,4 Reichweite, +20 HP, +6 Lethality | H2: 6 | I2: 22 | J2: 1 | K2: 0.4 | L2: 0 | M2: 0 | N2: 0 | O2: 20 | P2: 0 | Q2: 0 | R2: 0 | S2: 0 | T2: 0 | U2: 0 | V2: 0 | W2: 0 | X2: 0 | Y2: 0 | Z2: 0 | AA2: 0 | AB2: 0 | AC2: 0 | AD2: 6 | AE2: 0 | AF2: 0 | AG2: 0 | AH2: 0 | AI2: P_Glibber_Huepfer_2
A3: Glibberwerfer | B3: 0 | C3: Glibberwerfer - Hüpfer | D3: 10 | E3: 3 | F3: Flummi | G3: Abpraller: 3 → 6 · Slow: 15 % (1,5 s) → 20 % (2 s) +2 Schaden, +0,4 Reichweite, -0,15 s Abklingzeit, +10 % Angriffsanimation, +30 HP, +10 % Crit-Chance, +25 % Crit-Schaden, +8 Lethality | H3: 14 | I3: 48 | J3: 2 | K3: 0.4 | L3: 0.1 | M3: 0.15 | N3: 0 | O3: 30 | P3: 0 | Q3: 0 | R3: 0 | S3: 0 | T3: 0 | U3: 0 | V3: 0 | W3: 0 | X3: 0 | Y3: 0 | Z3: 0 | AA3: 0 | AB3: 0.1 | AC3: 0.25 | AD3: 8 | AE3: 0 | AF3: 0 | AG3: 0 | AH3: 0 | AI3: P_Glibber_Huepfer_3
A4: Glibberwerfer | B4: 1 | C4: Glibberwerfer - Klebrig | D4: 10 | E4: 2 | F4: Zähflüssig | G4: Slow: 15 % (1,5 s) → 30 % (2,5 s) +0,3 Reichweite, -0,1 s Abklingzeit, +15 HP, +10 % Armor Pen | H4: 6 | I4: 24 | J4: 0 | K4: 0.3 | L4: 0 | M4: 0.1 | N4: 0 | O4: 15 | P4: 0 | Q4: 0 | R4: 0 | S4: 0 | T4: 0 | U4: 0 | V4: 0 | W4: 0 | X4: 0 | Y4: 0 | Z4: 0 | AA4: 0 | AB4: 0 | AC4: 0 | AD4: 0 | AE4: 0.1 | AF4: 0 | AG4: 0 | AH4: 0 | AI4: P_Glibber_Klebrig_2
A5: Glibberwerfer | B5: 1 | C5: Glibberwerfer - Klebrig | D5: 10 | E5: 3 | F5: Dauerkleber | G5: Slow: 30 % (2,5 s) → 45 % (3 s) · Rüstungs-Shred: -4 pro Stapel (max. 3) +1 Schaden, -0,1 s Abklingzeit, +25 HP, +4 Lethality, +10 % Armor Pen | H5: 14 | I5: 50 | J5: 1 | K5: 0 | L5: 0 | M5: 0.1 | N5: 0 | O5: 25 | P5: 0 | Q5: 0 | R5: 0 | S5: 0 | T5: 0 | U5: 0 | V5: 0 | W5: 0 | X5: 0 | Y5: 0 | Z5: 0 | AA5: 0 | AB5: 0 | AC5: 0 | AD5: 4 | AE5: 0.1 | AF5: 0 | AG5: 0 | AH5: 0 | AI5: P_Glibber_Klebrig_3
A6: Glibberwerfer | B6: 2 | C6: Glibberwerfer - Pudding | D6: 10 | E6: 2 | F6: Wackelpudding | G6: +80 HP, +0,5 HP/s Regeneration, +25 Rüstung, +15 Magieresistenz, +6 % Omnivamp | H6: 6 | I6: 22 | J6: 0 | K6: 0 | L6: 0 | M6: 0 | N6: 0 | O6: 80 | P6: 0.5 | Q6: 0 | R6: 0 | S6: 0 | T6: 0 | U6: 0 | V6: 0 | W6: 0 | X6: 0 | Y6: 0 | Z6: 25 | AA6: 15 | AB6: 0 | AC6: 0 | AD6: 0 | AE6: 0 | AF6: 0 | AG6: 0 | AH6: 0.06 | AI6: P_Glibber_Pudding_2
A7: Glibberwerfer | B7: 2 | C7: Glibberwerfer - Pudding | D7: 10 | E7: 3 | F7: Gelatinewall | G7: Abpraller: 1 → 2 · Slow: 15 % (1,5 s) → 20 % (2 s) +1 Schaden, +160 HP, +1 HP/s Regeneration, +40 Rüstung, +30 Magieresistenz, +6 % Omnivamp | H7: 14 | I7: 46 | J7: 1 | K7: 0 | L7: 0 | M7: 0 | N7: 0 | O7: 160 | P7: 1 | Q7: 0 | R7: 0 | S7: 0 | T7: 0 | U7: 0 | V7: 0 | W7: 0 | X7: 0 | Y7: 0 | Z7: 40 | AA7: 30 | AB7: 0 | AC7: 0 | AD7: 0 | AE7: 0 | AF7: 0 | AG7: 0 | AH7: 0.06 | AI7: P_Glibber_Pudding_3
A8: Säuretümpel | B8: 0 | C8: Säuretümpel - Ätzer | D8: 10 | E8: 2 | F8: Zersetzend | G8: Rüstungs-Shred: -10 pro Stapel (max. 3) · MR-Shred: -10 pro Stapel (max. 3) +1 Schaden, +5 Magic Pen | H8: 8 | I8: 26 | J8: 1 | K8: 0 | L8: 0 | M8: 0 | N8: 0 | O8: 0 | P8: 0 | Q8: 0 | R8: 0 | S8: 0 | T8: 0 | U8: 0 | V8: 0 | W8: 0 | X8: 0 | Y8: 0 | Z8: 0 | AA8: 0 | AB8: 0 | AC8: 0 | AD8: 0 | AE8: 0 | AF8: 5 | AG8: 0 | AH8: 0 | AI8: P_Saeure_Aetzer_2
A9: Säuretümpel | B9: 0 | C9: Säuretümpel - Ätzer | D9: 10 | E9: 3 | F9: Totalauflösung | G9: Gift: 4 alle 0,5 s → 5 alle 0,5 s · Gift-Dauer: 3 s → 4 s · Rüstungs-Shred: -10 pro Stapel (max. 3) → -12 pro Stapel (max. 3) · MR-Shred: -10 pro Stapel (max. 3) → -12 pro Stapel (max. 3) · Shred %: -5 % pro Stapel +2 Schaden, +0,3 Reichweite, +5 Magic Pen, +15 % Magic Pen | H9: 16 | I9: 55 | J9: 2 | K9: 0.3 | L9: 0 | M9: 0 | N9: 0 | O9: 0 | P9: 0 | Q9: 0 | R9: 0 | S9: 0 | T9: 0 | U9: 0 | V9: 0 | W9: 0 | X9: 0 | Y9: 0 | Z9: 0 | AA9: 0 | AB9: 0 | AC9: 0 | AD9: 0 | AE9: 0 | AF9: 5 | AG9: 0.15 | AH9: 0 | AI9: P_Saeure_Aetzer_3
A10: Säuretümpel | B10: 1 | C10: Säuretümpel - Verdauer | D10: 10 | E10: 2 | F10: Magensaft | G10: Gift: 4 alle 0,5 s → 6 alle 0,5 s · Gift-Dauer: 3 s → 6 s · Anti-Heal: -30 % Heilung (3 s) -0,2 s Abklingzeit, +10 % Angriffsanimation | H10: 8 | I10: 26 | J10: 0 | K10: 0 | L10: 0.1 | M10: 0.2 | N10: 0 | O10: 0 | P10: 0 | Q10: 0 | R10: 0 | S10: 0 | T10: 0 | U10: 0 | V10: 0 | W10: 0 | X10: 0 | Y10: 0 | Z10: 0 | AA10: 0 | AB10: 0 | AC10: 0 | AD10: 0 | AE10: 0 | AF10: 0 | AG10: 0 | AH10: 0 | AI10: P_Saeure_Verdauer_2
A11: Säuretümpel | B11: 1 | C11: Säuretümpel - Verdauer | D11: 10 | E11: 3 | F11: Fressrausch | G11: Gift: 6 alle 0,5 s → 9 alle 0,5 s · Anti-Heal: -30 % Heilung (3 s) → -50 % Heilung (4 s) +1 Schaden, -0,2 s Abklingzeit, +15 % Magic Pen | H11: 16 | I11: 54 | J11: 1 | K11: 0 | L11: 0 | M11: 0.2 | N11: 0 | O11: 0 | P11: 0 | Q11: 0 | R11: 0 | S11: 0 | T11: 0 | U11: 0 | V11: 0 | W11: 0 | X11: 0 | Y11: 0 | Z11: 0 | AA11: 0 | AB11: 0 | AC11: 0 | AD11: 0 | AE11: 0 | AF11: 0 | AG11: 0.15 | AH11: 0 | AI11: P_Saeure_Verdauer_3
A12: Säuretümpel | B12: 2 | C12: Säuretümpel - Giftblase | D12: 10 | E12: 2 | F12: Blubberlache | G12: Neu: Flächenschaden · Einschlag: +6 · Flächenradius: 1,6 · Slow: 20 % (2 s) +30 HP | H12: 8 | I12: 28 | J12: 0 | K12: 0 | L12: 0 | M12: 0 | N12: 0 | O12: 30 | P12: 0 | Q12: 0 | R12: 0 | S12: 0 | T12: 0 | U12: 0 | V12: 0 | W12: 0 | X12: 0 | Y12: 0 | Z12: 0 | AA12: 0 | AB12: 0 | AC12: 0 | AD12: 0 | AE12: 0 | AF12: 0 | AG12: 0 | AH12: 0 | AI12: P_Saeure_Giftblase_2
A13: Säuretümpel | B13: 2 | C13: Säuretümpel - Giftblase | D13: 10 | E13: 3 | F13: Faulgrube | G13: Einschlag: +6 → +8 · Flächenradius: 1,6 → 2,6 · Slow: 20 % (2 s) → 30 % (2,5 s) · Anti-Heal: -30 % Heilung (3 s) +2 Schaden, +20 % Magic Pen | H13: 16 | I13: 56 | J13: 2 | K13: 0 | L13: 0 | M13: 0 | N13: 0 | O13: 0 | P13: 0 | Q13: 0 | R13: 0 | S13: 0 | T13: 0 | U13: 0 | V13: 0 | W13: 0 | X13: 0 | Y13: 0 | Z13: 0 | AA13: 0 | AB13: 0 | AC13: 0 | AD13: 0 | AE13: 0 | AF13: 0 | AG13: 0.2 | AH13: 0 | AI13: P_Saeure_Giftblase_3
... A37: Schleimabfluss | B37: 2 | C37: Schleimabfluss - Kanalisation | D37: 10 | E37: 3 | F37: Verwertung | G37: Sogdauer: 2 s → 2,5 s · Sogradius: 3 → 3,5 · Anti-Heal: -50 % Heilung (4 s) +100 HP, +2 HP/s Regeneration, +6 % Omnivamp | H37: 16 | I37: 58 | J37: 0 | K37: 0 | L37: 0 | M37: 0 | N37: 0 | O37: 100 | P37: 2 | Q37: 0 | R37: 0 | S37: 0 | T37: 0 | U37: 0 | V37: 0 | W37: 0 | X37: 0 | Y37: 0 | Z37: 0 | AA37: 0 | AB37: 0 | AC37: 0 | AD37: 0 | AE37: 0 | AF37: 0 | AG37: 0 | AH37: 0.06 | AI37: P_Abfluss_Kanal_3

Sheet Projektile
A1: Prefab-Name | B1: Turm | C1: baseDmg | D1: rotationAngleOffset | E1: doRotation | F1: lookAtTarget | G1: hideTilCollision | H1: canFindNewTarget | I1: speed | J1: turnSpeed | K1: maxRedirectAngle | L1: damageType | M1: mode | N1: hitEffects.antiHealPercent | O1: hitEffects.antiHealDuration | P1: hitEffects.armorShredFlat | Q1: hitEffects.mrShredFlat | R1: hitEffects.shredPercent | S1: hitEffects.shredDuration | T1: hitEffects.shredMaxStacks | U1: hitEffects.shredKey | V1: hitEffects.slowAmount | W1: hitEffects.slowDuration | X1: aoeRadius | Y1: dotDuration | Z1: dotInterval | AA1: dotDamagePerTick | AB1: chainDamage | AC1: chainCount | AD1: chainDamageFalloff | AE1: chainRadius | AF1: knockbackDistance | AG1: knockbackDuration | AH1: splitterCount | AI1: splitterDamage | AJ1: pierceCount | AK1: blackHolePullDuration | AL1: blackHoleRadius | AM1: stickyDelay | AN1: stickyAoeRadius | AO1: stickyAoeDamage | AP1: chainLinkRadius | AQ1: chainSlowAmount | AR1: chainLinkDamage | AS1: splitterPrefab
A2: P_Glibber_Basis | B2: Glibberwerfer | C2: 0 | D2: 0 | E2: nein | F2: ja | G2: nein | H2: 1 | I2: 9 | J2: 360 | K2: 90 | L2: Physical | M2: Default | N2: 0 | O2: 3 | P2: 0 | Q2: 0 | R2: 0 | S2: 4 | T2: 3 | U2: shred | V2: 0.15 | W2: 1.5 | X2: 1.5 | Y2: 3 | Z2: 0.5 | AA2: 5 | AB2: 10 | AC2: 3 | AD2: 0.2 | AE2: 3 | AF2: 1.5 | AG2: 0.2 | AH2: 5 | AI2: 10 | AJ2: 5 | AK2: 2 | AL2: 3 | AM2: 2 | AN2: 1.5 | AO2: 5 | AP2: 4 | AQ2: 0.4 | AR2: 5
A3: P_Glibber_Huepfer_2 | B3: Glibberwerfer | C3: 0 | D3: 0 | E3: nein | F3: ja | G3: nein | H3: 3 | I3: 9 | J3: 360 | K3: 90 | L3: Physical | M3: Default | N3: 0 | O3: 3 | P3: 0 | Q3: 0 | R3: 0 | S3: 4 | T3: 3 | U3: shred | V3: 0.15 | W3: 1.5 | X3: 1.5 | Y3: 3 | Z3: 0.5 | AA3: 5 | AB3: 10 | AC3: 3 | AD3: 0.2 | AE3: 3 | AF3: 1.5 | AG3: 0.2 | AH3: 5 | AI3: 10 | AJ3: 5 | AK3: 2 | AL3: 3 | AM3: 2 | AN3: 1.5 | AO3: 5 | AP3: 4 | AQ3: 0.4 | AR3: 5
A4: P_Glibber_Huepfer_3 | B4: Glibberwerfer | C4: 0 | D4: 0 | E4: nein | F4: ja | G4: nein | H4: 6 | I4: 9 | J4: 360 | K4: 90 | L4: Physical | M4: Default | N4: 0 | O4: 3 | P4: 0 | Q4: 0 | R4: 0 | S4: 4 | T4: 3 | U4: shred | V4: 0.2 | W4: 2 | X4: 1.5 | Y4: 3 | Z4: 0.5 | AA4: 5 | AB4: 10 | AC4: 3 | AD4: 0.2 | AE4: 3 | AF4: 1.5 | AG4: 0.2 | AH4: 5 | AI4: 10 | AJ4: 5 | AK4: 2 | AL4: 3 | AM4: 2 | AN4: 1.5 | AO4: 5 | AP4: 4 | AQ4: 0.4 | AR4: 5
A5: P_Glibber_Klebrig_2 | B5: Glibberwerfer | C5: 0 | D5: 0 | E5: nein | F5: ja | G5: nein | H5: 1 | I5: 9 | J5: 360 | K5: 90 | L5: Physical | M5: Default | N5: 0 | O5: 3 | P5: 0 | Q5: 0 | R5: 0 | S5: 4 | T5: 3 | U5: shred | V5: 0.3 | W5: 2.5 | X5: 1.5 | Y5: 3 | Z5: 0.5 | AA5: 5 | AB5: 10 | AC5: 3 | AD5: 0.2 | AE5: 3 | AF5: 1.5 | AG5: 0.2 | AH5: 5 | AI5: 10 | AJ5: 5 | AK5: 2 | AL5: 3 | AM5: 2 | AN5: 1.5 | AO5: 5 | AP5: 4 | AQ5: 0.4 | AR5: 5
A6: P_Glibber_Klebrig_3 | B6: Glibberwerfer | C6: 0 | D6: 0 | E6: nein | F6: ja | G6: nein | H6: 1 | I6: 9 | J6: 360 | K6: 90 | L6: Physical | M6: Default | N6: 0 | O6: 3 | P6: 4 | Q6: 0 | R6: 0 | S6: 4 | T6: 3 | U6: glibber | V6: 0.45 | W6: 3 | X6: 1.5 | Y6: 3 | Z6: 0.5 | AA6: 5 | AB6: 10 | AC6: 3 | AD6: 0.2 | AE6: 3 | AF6: 1.5 | AG6: 0.2 | AH6: 5 | AI6: 10 | AJ6: 5 | AK6: 2 | AL6: 3 | AM6: 2 | AN6: 1.5 | AO6: 5 | AP6: 4 | AQ6: 0.4 | AR6: 5
A7: P_Glibber_Pudding_2 | B7: Glibberwerfer | C7: 0 | D7: 0 | E7: nein | F7: ja | G7: nein | H7: 1 | I7: 9 | J7: 360 | K7: 90 | L7: Physical | M7: Default | N7: 0 | O7: 3 | P7: 0 | Q7: 0 | R7: 0 | S7: 4 | T7: 3 | U7: shred | V7: 0.15 | W7: 1.5 | X7: 1.5 | Y7: 3 | Z7: 0.5 | AA7: 5 | AB7: 10 | AC7: 3 | AD7: 0.2 | AE7: 3 | AF7: 1.5 | AG7: 0.2 | AH7: 5 | AI7: 10 | AJ7: 5 | AK7: 2 | AL7: 3 | AM7: 2 | AN7: 1.5 | AO7: 5 | AP7: 4 | AQ7: 0.4 | AR7: 5
A8: P_Glibber_Pudding_3 | B8: Glibberwerfer | C8: 0 | D8: 0 | E8: nein | F8: ja | G8: nein | H8: 2 | I8: 9 | J8: 360 | K8: 90 | L8: Physical | M8: Default | N8: 0 | O8: 3 | P8: 0 | Q8: 0 | R8: 0 | S8: 4 | T8: 3 | U8: shred | V8: 0.2 | W8: 2 | X8: 1.5 | Y8: 3 | Z8: 0.5 | AA8: 5 | AB8: 10 | AC8: 3 | AD8: 0.2 | AE8: 3 | AF8: 1.5 | AG8: 0.2 | AH8: 5 | AI8: 10 | AJ8: 5 | AK8: 2 | AL8: 3 | AM8: 2 | AN8: 1.5 | AO8: 5 | AP8: 4 | AQ8: 0.4 | AR8: 5
A9: P_Saeure_Basis | B9: Säuretümpel | C9: 0 | D9: 0 | E9: nein | F9: ja | G9: nein | H9: 0 | I9: 7 | J9: 360 | K9: 90 | L9: Magic | M9: DoT | N9: 0 | O9: 3 | P9: 0 | Q9: 0 | R9: 0 | S9: 4 | T9: 3 | U9: shred | V9: 0 | W9: 2 | X9: 1.5 | Y9: 3 | Z9: 0.5 | AA9: 4 | AB9: 10 | AC9: 3 | AD9: 0.2 | AE9: 3 | AF9: 1.5 | AG9: 0.2 | AH9: 5 | AI9: 10 | AJ9: 5 | AK9: 2 | AL9: 3 | AM9: 2 | AN9: 1.5 | AO9: 5 | AP9: 4 | AQ9: 0.4 | AR9: 5
A10: P_Saeure_Aetzer_2 | B10: Säuretümpel | C10: 0 | D10: 0 | E10: nein | F10: ja | G10: nein | H10: 0 | I10: 7 | J10: 360 | K10: 90 | L10: Magic | M10: DoT | N10: 0 | O10: 3 | P10: 10 | Q10: 10 | R10: 0 | S10: 4 | T10: 3 | U10: saeure | V10: 0 | W10: 2 | X10: 1.5 | Y10: 3 | Z10: 0.5 | AA10: 4 | AB10: 10 | AC10: 3 | AD10: 0.2 | AE10: 3 | AF10: 1.5 | AG10: 0.2 | AH10: 5 | AI10: 10 | AJ10: 5 | AK10: 2 | AL10: 3 | AM10: 2 | AN10: 1.5 | AO10: 5 | AP10: 4 | AQ10: 0.4 | AR10: 5
A11: P_Saeure_Aetzer_3 | B11: Säuretümpel | C11: 0 | D11: 0 | E11: nein | F11: ja | G11: nein | H11: 0 | I11: 7 | J11: 360 | K11: 90 | L11: Magic | M11: DoT | N11: 0 | O11: 3 | P11: 12 | Q11: 12 | R11: 0.05 | S11: 6 | T11: 3 | U11: saeure | V11: 0 | W11: 2 | X11: 1.5 | Y11: 4 | Z11: 0.5 | AA11: 5 | AB11: 10 | AC11: 3 | AD11: 0.2 | AE11: 3 | AF11: 1.5 | AG11: 0.2 | AH11: 5 | AI11: 10 | AJ11: 5 | AK11: 2 | AL11: 3 | AM11: 2 | AN11: 1.5 | AO11: 5 | AP11: 4 | AQ11: 0.4 | AR11: 5
A12: P_Saeure_Verdauer_2 | B12: Säuretümpel | C12: 0 | D12: 0 | E12: nein | F12: ja | G12: nein | H12: 0 | I12: 7 | J12: 360 | K12: 90 | L12: Magic | M12: DoT | N12: 0.3 | O12: 3 | P12: 0 | Q12: 0 | R12: 0 | S12: 4 | T12: 3 | U12: shred | V12: 0 | W12: 2 | X12: 1.5 | Y12: 6 | Z12: 0.5 | AA12: 6 | AB12: 10 | AC12: 3 | AD12: 0.2 | AE12: 3 | AF12: 1.5 | AG12: 0.2 | AH12: 5 | AI12: 10 | AJ12: 5 | AK12: 2 | AL12: 3 | AM12: 2 | AN12: 1.5 | AO12: 5 | AP12: 4 | AQ12: 0.4 | AR12: 5
A13: P_Saeure_Verdauer_3 | B13: Säuretümpel | C13: 0 | D13: 0 | E13: nein | F13: ja | G13: nein | H13: 0 | I13: 7 | J13: 360 | K13: 90 | L13: Magic | M13: DoT | N13: 0.5 | O13: 4 | P13: 0 | Q13: 0 | R13: 0 | S13: 4 | T13: 3 | U13: shred | V13: 0 | W13: 2 | X13: 1.5 | Y13: 6 | Z13: 0.5 | AA13: 9 | AB13: 10 | AC13: 3 | AD13: 0.2 | AE13: 3 | AF13: 1.5 | AG13: 0.2 | AH13: 5 | AI13: 10 | AJ13: 5 | AK13: 2 | AL13: 3 | AM13: 2 | AN13: 1.5 | AO13: 5 | AP13: 4 | AQ13: 0.4 | AR13: 5
... A18: P_Spalt_Schleimling_Klebrig_3 | B18: Spaltschleim | C18: 0 | D18: 0 | E18: nein | F18: ja | G18: nein | H18: 0 | I18: 9 | J18: 360 | K18: 90 | L18: Physical | M18: Default | N18: 0 | O18: 3 | P18: 0 | Q18: 0 | R18: 0 | S18: 4 | T18: 3 | U18: shred | V18: 0.4 | W18: 3 | X18: 1.5 | Y18: 3 | Z18: 0.5 | AA18: 5 | AB18: 10 | AC18: 3 | AD18: 0.2 | AE18: 3 | AF18: 1.5 | AG18: 0.2 | AH18: 5 | AI18: 10 | AJ18: 5 | AK18: 2 | AL18: 3 | AM18: 2 | AN18: 1.5 | AO18: 5 | AP18: 4 | AQ18: 0.4 | AR18: 5
A19: P_Spalt_Basis | B19: Spaltschleim | C19: 0 | D19: 0 | E19: nein | F19: ja | G19: nein | H19: 0 | I19: 8 | J19: 360 | K19: 90 | L19: Physical | M19: Splitter | N19: 0 | O19: 3 | P19: 0 | Q19: 0 | R19: 0 | S19: 4 | T19: 3 | U19: shred | V19: 0 | W19: 2 | X19: 1.5 | Y19: 3 | Z19: 0.5 | AA19: 5 | AB19: 10 | AC19: 3 | AD19: 0.2 | AE19: 3 | AF19: 1.5 | AG19: 0.2 | AH19: 3 | AI19: 3 | AJ19: 5 | AK19: 2 | AL19: 3 | AM19: 2 | AN19: 1.5 | AO19: 5 | AP19: 4 | AQ19: 0.4 | AR19: 5 | AS19: P_Spalt_Schleimling
A20: P_Spalt_Teiler_2 | B20: Spaltschleim | C20: 0 | D20: 0 | E20: nein | F20: ja | G20: nein | H20: 0 | I20: 8 | J20: 360 | K20: 90 | L20: Physical | M20: Splitter | N20: 0 | O20: 3 | P20: 0 | Q20: 0 | R20: 0 | S20: 4 | T20: 3 | U20: shred | V20: 0 | W20: 2 | X20: 1.5 | Y20: 3 | Z20: 0.5 | AA20: 5 | AB20: 10 | AC20: 3 | AD20: 0.2 | AE20: 3 | AF20: 1.5 | AG20: 0.2 | AH20: 5 | AI20: 3 | AJ20: 5 | AK20: 2 | AL20: 3 | AM20: 2 | AN20: 1.5 | AO20: 5 | AP20: 4 | AQ20: 0.4 | AR20: 5 | AS20: P_Spalt_Schleimling
A21: P_Spalt_Teiler_3 | B21: Spaltschleim | C21: 0 | D21: 0 | E21: nein | F21: ja | G21: nein | H21: 0 | I21: 8 | J21: 360 | K21: 90 | L21: Physical | M21: Splitter | N21: 0 | O21: 3 | P21: 0 | Q21: 0 | R21: 0 | S21: 4 | T21: 3 | U21: shred | V21: 0 | W21: 2 | X21: 1.5 | Y21: 3 | Z21: 0.5 | AA21: 5 | AB21: 10 | AC21: 3 | AD21: 0.2 | AE21: 3 | AF21: 1.5 | AG21: 0.2 | AH21: 8 | AI21: 4 | AJ21: 5 | AK21: 2 | AL21: 3 | AM21: 2 | AN21: 1.5 | AO21: 5 | AP21: 4 | AQ21: 0.4 | AR21: 5 | AS21: P_Spalt_Schleimling
A22: P_Spalt_Verschmelzer_2 | B22: Spaltschleim | C22: 0 | D22: 0 | E22: nein | F22: ja | G22: nein | H22: 0 | I22: 8 | J22: 360 | K22: 90 | L22: Physical | M22: Splitter | N22: 0 | O22: 3 | P22: 0 | Q22: 0 | R22: 0 | S22: 4 | T22: 3 | U22: shred | V22: 0 | W22: 2 | X22: 1.5 | Y22: 3 | Z22: 0.5 | AA22: 5 | AB22: 10 | AC22: 3 | AD22: 0.2 | AE22: 3 | AF22: 1.5 | AG22: 0.2 | AH22: 4 | AI22: 3 | AJ22: 5 | AK22: 2 | AL22: 3 | AM22: 2 | AN22: 1.5 | AO22: 5 | AP22: 4 | AQ22: 0.4 | AR22: 5 | AS22: P_Spalt_Schleimling
A23: P_Spalt_Verschmelzer_3 | B23: Spaltschleim | C23: 4 | D23: 0 | E23: nein | F23: ja | G23: nein | H23: 0 | I23: 8 | J23: 360 | K23: 90 | L23: Physical | M23: Splitter | N23: 0 | O23: 3 | P23: 0 | Q23: 0 | R23: 0 | S23: 4 | T23: 3 | U23: shred | V23: 0 | W23: 2 | X23: 1.5 | Y23: 3 | Z23: 0.5 | AA23: 5 | AB23: 10 | AC23: 3 | AD23: 0.2 | AE23: 3 | AF23: 1.5 | AG23: 0.2 | AH23: 4 | AI23: 6 | AJ23: 5 | AK23: 2 | AL23: 3 | AM23: 2 | AN23: 1.5 | AO23: 5 | AP23: 4 | AQ23: 0.4 | AR23: 5 | AS23: P_Spalt_Schleimling
A24: P_Spalt_Brut_2 | B24: Spaltschleim | C24: 0 | D24: 0 | E24: nein | F24: ja | G24: nein | H24: 0 | I24: 8 | J24: 360 | K24: 90 | L24: Physical | M24: Splitter | N24: 0 | O24: 3 | P24: 0 | Q24: 0 | R24: 0 | S24: 4 | T24: 3 | U24: shred | V24: 0 | W24: 2 | X24: 1.5 | Y24: 3 | Z24: 0.5 | AA24: 5 | AB24: 10 | AC24: 3 | AD24: 0.2 | AE24: 3 | AF24: 1.5 | AG24: 0.2 | AH24: 5 | AI24: 3 | AJ24: 5 | AK24: 2 | AL24: 3 | AM24: 2 | AN24: 1.5 | AO24: 5 | AP24: 4 | AQ24: 0.4 | AR24: 5 | AS24: P_Spalt_Schleimling_Klebrig_2
A25: P_Spalt_Brut_3 | B25: Spaltschleim | C25: 0 | D25: 0 | E25: nein | F25: ja | G25: nein | H25: 0 | I25: 8 | J25: 360 | K25: 90 | L25: Physical | M25: Splitter | N25: 0 | O25: 3 | P25: 0 | Q25: 0 | R25: 0 | S25: 4 | T25: 3 | U25: shred | V25: 0 | W25: 2 | X25: 1.5 | Y25: 3 | Z25: 0.5 | AA25: 5 | AB25: 10 | AC25: 3 | AD25: 0.2 | AE25: 3 | AF25: 1.5 | AG25: 0.2 | AH25: 6 | AI25: 4 | AJ25: 5 | AK25: 2 | AL25: 3 | AM25: 2 | AN25: 1.5 | AO25: 5 | AP25: 4 | AQ25: 0.4 | AR25: 5 | AS25: P_Spalt_Schleimling_Klebrig_3
A26: P_Faden_Basis | B26: Klebfadenturm | C26: 0 | D26: 0 | E26: nein | F26: ja | G26: nein | H26: 0 | I26: 9 | J26: 360 | K26: 90 | L26: Physical | M26: Chainslow | N26: 0 | O26: 3 | P26: 0 | Q26: 0 | R26: 0 | S26: 4 | T26: 3 | U26: shred | V26: 0 | W26: 2 | X26: 1.5 | Y26: 3 | Z26: 0.5 | AA26: 5 | AB26: 10 | AC26: 3 | AD26: 0.2 | AE26: 3 | AF26: 1.5 | AG26: 0.2 | AH26: 5 | AI26: 10 | AJ26: 5 | AK26: 2 | AL26: 3 | AM26: 2 | AN26: 1.5 | AO26: 5 | AP26: 4 | AQ26: 0.4 | AR26: 3
A27: P_Faden_Seide_2 | B27: Klebfadenturm | C27: 0 | D27: 0 | E27: nein | F27: ja | G27: nein | H27: 0 | I27: 9 | J27: 360 | K27: 90 | L27: Physical | M27: Chainslow | N27: 0 | O27: 3 | P27: 0 | Q27: 0 | R27: 0 | S27: 4 | T27: 3 | U27: shred | V27: 0 | W27: 2 | X27: 1.5 | Y27: 3 | Z27: 0.5 | AA27: 5 | AB27: 10 | AC27: 3 | AD27: 0.2 | AE27: 3 | AF27: 1.5 | AG27: 0.2 | AH27: 5 | AI27: 10 | AJ27: 5 | AK27: 2 | AL27: 3 | AM27: 2 | AN27: 1.5 | AO27: 5 | AP27: 5 | AQ27: 0.55 | AR27: 4
A28: P_Faden_Seide_3 | B28: Klebfadenturm | C28: 0 | D28: 0 | E28: nein | F28: ja | G28: nein | H28: 0 | I28: 9 | J28: 360 | K28: 90 | L28: Physical | M28: Chainslow | N28: 0 | O28: 3 | P28: 0 | Q28: 0 | R28: 0 | S28: 4 | T28: 3 | U28: shred | V28: 0 | W28: 2 | X28: 1.5 | Y28: 3 | Z28: 0.5 | AA28: 5 | AB28: 10 | AC28: 3 | AD28: 0.2 | AE28: 3 | AF28: 1.5 | AG28: 0.2 | AH28: 5 | AI28: 10 | AJ28: 5 | AK28: 2 | AL28: 3 | AM28: 2 | AN28: 1.5 | AO28: 5 | AP28: 6 | AQ28: 0.65 | AR28: 6
A29: P_Faden_Blase_2 | B29: Klebfadenturm | C29: 0 | D29: 0 | E29: nein | F29: ja | G29: nein | H29: 0 | I29: 9 | J29: 360 | K29: 90 | L29: Physical | M29: Sticky | N29: 0 | O29: 3 | P29: 0 | Q29: 0 | R29: 0 | S29: 4 | T29: 3 | U29: shred | V29: 0 | W29: 2 | X29: 1.5 | Y29: 3 | Z29: 0.5 | AA29: 5 | AB29: 10 | AC29: 3 | AD29: 0.2 | AE29: 3 | AF29: 1.5 | AG29: 0.2 | AH29: 5 | AI29: 10 | AJ29: 5 | AK29: 2 | AL29: 3 | AM29: 2 | AN29: 1.5 | AO29: 15 | AP29: 4 | AQ29: 0.4 | AR29: 5
A30: P_Faden_Blase_3 | B30: Klebfadenturm | C30: 0 | D30: 0 | E30: nein | F30: ja | G30: nein | H30: 0 | I30: 9 | J30: 360 | K30: 90 | L30: Physical | M30: Sticky | N30: 0.3 | O30: 3 | P30: 0 | Q30: 0 | R30: 0 | S30: 4 | T30: 3 | U30: shred | V30: 0 | W30: 2 | X30: 1.5 | Y30: 3 | Z30: 0.5 | AA30: 5 | AB30: 10 | AC30: 3 | AD30: 0.2 | AE30: 3 | AF30: 1.5 | AG30: 0.2 | AH30: 5 | AI30: 10 | AJ30: 5 | AK30: 2 | AL30: 3 | AM30: 1.2 | AN30: 2.2 | AO30: 30 | AP30: 4 | AQ30: 0.4 | AR30: 5
A31: P_Faden_Leim_2 | B31: Klebfadenturm | C31: 0 | D31: 0 | E31: nein | F31: ja | G31: nein | H31: 0 | I31: 9 | J31: 360 | K31: 90 | L31: Physical | M31: Chainslow | N31: 0 | O31: 3 | P31: 0 | Q31: 0 | R31: 0 | S31: 4 | T31: 3 | U31: shred | V31: 0 | W31: 2 | X31: 1.5 | Y31: 3 | Z31: 0.5 | AA31: 5 | AB31: 10 | AC31: 3 | AD31: 0.2 | AE31: 3 | AF31: 1.5 | AG31: 0.2 | AH31: 5 | AI31: 10 | AJ31: 5 | AK31: 2 | AL31: 3 | AM31: 2 | AN31: 1.5 | AO31: 5 | AP31: 4 | AQ31: 0.5 | AR31: 3
A32: P_Faden_Leim_3 | B32: Klebfadenturm | C32: 0 | D32: 0 | E32: nein | F32: ja | G32: nein | H32: 0 | I32: 9 | J32: 360 | K32: 90 | L32: Physical | M32: Chainslow | N32: 0 | O32: 3 | P32: 0 | Q32: 0 | R32: 0 | S32: 4 | T32: 3 | U32: shred | V32: 0 | W32: 2 | X32: 1.5 | Y32: 3 | Z32: 0.5 | AA32: 5 | AB32: 10 | AC32: 3 | AD32: 0.2 | AE32: 3 | AF32: 1.5 | AG32: 0.2 | AH32: 5 | AI32: 10 | AJ32: 5 | AK32: 2 | AL32: 3 | AM32: 2 | AN32: 1.5 | AO32: 5 | AP32: 5 | AQ32: 0.55 | AR32: 4
A33: P_Qualle_Basis | B33: Quallenturm | C33: 0 | D33: 0 | E33: nein | F33: ja | G33: nein | H33: 0 | I33: 10 | J33: 360 | K33: 90 | L33: Magic | M33: ChainLightning | N33: 0 | O33: 3 | P33: 0 | Q33: 0 | R33: 0 | S33: 4 | T33: 3 | U33: shred | V33: 0 | W33: 2 | X33: 1.5 | Y33: 3 | Z33: 0.5 | AA33: 5 | AB33: 8 | AC33: 2 | AD33: 0.2 | AE33: 3 | AF33: 1.5 | AG33: 0.2 | AH33: 5 | AI33: 10 | AJ33: 5 | AK33: 2 | AL33: 3 | AM33: 2 | AN33: 1.5 | AO33: 5 | AP33: 4 | AQ33: 0.4 | AR33: 5
A34: P_Qualle_Gewitter_2 | B34: Quallenturm | C34: 0 | D34: 0 | E34: nein | F34: ja | G34: nein | H34: 0 | I34: 10 | J34: 360 | K34: 90 | L34: Magic | M34: ChainLightning | N34: 0 | O34: 3 | P34: 0 | Q34: 0 | R34: 0 | S34: 4 | T34: 3 | U34: shred | V34: 0 | W34: 2 | X34: 1.5 | Y34: 3 | Z34: 0.5 | AA34: 5 | AB34: 8 | AC34: 4 | AD34: 0.2 | AE34: 3.5 | AF34: 1.5 | AG34: 0.2 | AH34: 5 | AI34: 10 | AJ34: 5 | AK34: 2 | AL34: 3 | AM34: 2 | AN34: 1.5 | AO34: 5 | AP34: 4 | AQ34: 0.4 | AR34: 5
A35: P_Qualle_Gewitter_3 | B35: Quallenturm | C35: 0 | D35: 0 | E35: nein | F35: ja | G35: nein | H35: 0 | I35: 10 | J35: 360 | K35: 90 | L35: Magic | M35: ChainLightning | N35: 0 | O35: 3 | P35: 0 | Q35: 0 | R35: 0 | S35: 4 | T35: 3 | U35: shred | V35: 0 | W35: 2 | X35: 1.5 | Y35: 3 | Z35: 0.5 | AA35: 5 | AB35: 9 | AC35: 7 | AD35: 0.1 | AE35: 4 | AF35: 1.5 | AG35: 0.2 | AH35: 5 | AI35: 10 | AJ35: 5 | AK35: 2 | AL35: 3 | AM35: 2 | AN35: 1.5 | AO35: 5 | AP35: 4 | AQ35: 0.4 | AR35: 5
A36: P_Qualle_Stachel_2 | B36: Quallenturm | C36: 0 | D36: 0 | E36: nein | F36: ja | G36: nein | H36: 0 | I36: 10 | J36: 360 | K36: 90 | L36: Magic | M36: ChainLightning | N36: 0 | O36: 3 | P36: 0 | Q36: 0 | R36: 0 | S36: 4 | T36: 3 | U36: shred | V36: 0 | W36: 2 | X36: 1.5 | Y36: 3 | Z36: 0.5 | AA36: 5 | AB36: 20 | AC36: 1 | AD36: 0.2 | AE36: 3 | AF36: 1.5 | AG36: 0.2 | AH36: 5 | AI36: 10 | AJ36: 5 | AK36: 2 | AL36: 3 | AM36: 2 | AN36: 1.5 | AO36: 5 | AP36: 4 | AQ36: 0.4 | AR36: 5
A37: P_Qualle_Stachel_3 | B37: Quallenturm | C37: 0 | D37: 0 | E37: nein | F37: ja | G37: nein | H37: 0 | I37: 10 | J37: 360 | K37: 90 | L37: Magic | M37: ChainLightning | N37: 0 | O37: 3 | P37: 0 | Q37: 0 | R37: 0 | S37: 4 | T37: 3 | U37: shred | V37: 0 | W37: 2 | X37: 1.5 | Y37: 3 | Z37: 0.5 | AA37: 5 | AB37: 34 | AC37: 1 | AD37: 0.2 | AE37: 3 | AF37: 1.5 | AG37: 0.2 | AH37: 5 | AI37: 10 | AJ37: 5 | AK37: 2 | AL37: 3 | AM37: 2 | AN37: 1.5 | AO37: 5 | AP37: 4 | AQ37: 0.4 | AR37: 5
... A46: P_Abfluss_Kanal_3 | B46: Schleimabfluss | C46: 0 | D46: 0 | E46: nein | F46: ja | G46: nein | H46: 0 | I46: 6 | J46: 360 | K46: 90 | L46: Magic | M46: BlackHole | N46: 0.5 | O46: 4 | P46: 0 | Q46: 0 | R46: 0 | S46: 4 | T46: 3 | U46: shred | V46: 0 | W46: 2 | X46: 1.5 | Y46: 3 | Z46: 0.5 | AA46: 5 | AB46: 10 | AC46: 3 | AD46: 0.2 | AE46: 3 | AF46: 1.5 | AG46: 0.2 | AH46: 5 | AI46: 10 | AJ46: 5 | AK46: 2.5 | AL46: 3.5 | AM46: 2 | AN46: 1.5 | AO46: 5 | AP46: 4 | AQ46: 0.4 | AR46: 5

Sheet Kumuliert
A1: Turm | B1: Pfad-Nr | C1: Pfad | D1: Level | E1: Schaden | F1: Abklingzeit (s) | G1: DPS | H1: Reichweite | I1: HP | J1: Rüstung | K1: Magieresistenz | L1: Crit-Chance | M1: Lethality | N1: Armor Pen % | O1: Magic Pen flat | P1: Magic Pen % | Q1: Omnivamp
A2: Glibberwerfer | C2: Basis | D2: 1 | E2: =INDEX(Türme!$N$2:$N$7,MATCH($A2,Türme!$A$2:$A$7,0)) -> 8 | F2: =MAX(0.1,INDEX(Türme!$O$2:$O$7,MATCH($A2,Türme!$A$2:$A$7,0))) -> 1.6 | G2: =E2/F2 -> 5 | H2: =INDEX(Türme!$L$2:$L$7,MATCH($A2,Türme!$A$2:$A$7,0)) -> 6 | I2: =INDEX(Türme!$G$2:$G$7,MATCH($A2,Türme!$A$2:$A$7,0)) -> 110 | J2: =INDEX(Türme!$I$2:$I$7,MATCH($A2,Türme!$A$2:$A$7,0)) -> 5 | K2: =INDEX(Türme!$J$2:$J$7,MATCH($A2,Türme!$A$2:$A$7,0)) -> 0 | L2: =MIN(1,INDEX(Türme!$R$2:$R$7,MATCH($A2,Türme!$A$2:$A$7,0))) -> 0 | M2: =INDEX(Türme!$T$2:$T$7,MATCH($A2,Türme!$A$2:$A$7,0)) -> 0 | N2: =MIN(1,INDEX(Türme!$U$2:$U$7,MATCH($A2,Türme!$A$2:$A$7,0))) -> 0 | O2: =INDEX(Türme!$V$2:$V$7,MATCH($A2,Türme!$A$2:$A$7,0)) -> 0 | P2: =MIN(1,INDEX(Türme!$W$2:$W$7,MATCH($A2,Türme!$A$2:$A$7,0))) -> 0 | Q2: =MIN(1,INDEX(Türme!$X$2:$X$7,MATCH($A2,Türme!$A$2:$A$7,0))) -> 0
A3: Glibberwerfer | B3: 0 | C3: Glibberwerfer - Hüpfer | D3: 2 | E3: =INDEX(Türme!$N$2:$N$7,MATCH($A3,Türme!$A$2:$A$7,0)) + SUMIFS(Upgrades!$J$2:$J$37,Upgrades!$A$2:$A$37,$A3,Upgrades!$B$2:$B$37,$B3,Upgrades!$E$2:$E$37,"<="&$D3) + SUMIFS(Upgrades!$W$2:$W$37,Upgrades!$A$2:$A$37,$A3,Upgrades!$B$2:$B$37,$B3,Upgrades!$E$2:$E$37,"<="&$D3) -> 9 | F3: =MAX(0.1,INDEX(Türme!$O$2:$O$7,MATCH($A3,Türme!$A$2:$A$7,0)) - SUMIFS(Upgrades!$M$2:$M$37,Upgrades!$A$2:$A$37,$A3,Upgrades!$B$2:$B$37,$B3,Upgrades!$E$2:$E$37,"<="&$D3) - SUMIFS(Upgrades!$Y$2:$Y$37,Upgrades!$A$2:$A$37,$A3,Upgrades!$B$2:$B$37,$B3,Upgrades!$E$2:$E$37,"<="&$D3)) -> 1.6 | G3: =E3/F3 -> 5.625 | H3: =INDEX(Türme!$L$2:$L$7,MATCH($A3,Türme!$A$2:$A$7,0)) + SUMIFS(Upgrades!$K$2:$K$37,Upgrades!$A$2:$A$37,$A3,Upgrades!$B$2:$B$37,$B3,Upgrades!$E$2:$E$37,"<="&$D3) + SUMIFS(Upgrades!$X$2:$X$37,Upgrades!$A$2:$A$37,$A3,Upgrades!$B$2:$B$37,$B3,Upgrades!$E$2:$E$37,"<="&$D3) -> 6.4 | I3: =INDEX(Türme!$G$2:$G$7,MATCH($A3,Türme!$A$2:$A$7,0)) + SUMIFS(Upgrades!$O$2:$O$37,Upgrades!$A$2:$A$37,$A3,Upgrades!$B$2:$B$37,$B3,Upgrades!$E$2:$E$37,"<="&$D3) + SUMIFS(Upgrades!$U$2:$U$37,Upgrades!$A$2:$A$37,$A3,Upgrades!$B$2:$B$37,$B3,Upgrades!$E$2:$E$37,"<="&$D3) -> 130 | J3: =INDEX(Türme!$I$2:$I$7,MATCH($A3,Türme!$A$2:$A$7,0)) + SUMIFS(Upgrades!$Z$2:$Z$37,Upgrades!$A$2:$A$37,$A3,Upgrades!$B$2:$B$37,$B3,Upgrades!$E$2:$E$37,"<="&$D3) -> 5 | K3: =INDEX(Türme!$J$2:$J$7,MATCH($A3,Türme!$A$2:$A$7,0)) + SUMIFS(Upgrades!$AA$2:$AA$37,Upgrades!$A$2:$A$37,$A3,Upgrades!$B$2:$B$37,$B3,Upgrades!$E$2:$E$37,"<="&$D3) -> 0 | L3: =MIN(1,INDEX(Türme!$R$2:$R$7,MATCH($A3,Türme!$A$2:$A$7,0)) + SUMIFS(Upgrades!$AB$2:$AB$37,Upgrades!$A$2:$A$37,$A3,Upgrades!$B$2:$B$37,$B3,Upgrades!$E$2:$E$37,"<="&$D3)) -> 0 | M3: =INDEX(Türme!$T$2:$T$7,MATCH($A3,Türme!$A$2:$A$7,0)) + SUMIFS(Upgrades!$AD$2:$AD$37,Upgrades!$A$2:$A$37,$A3,Upgrades!$B$2:$B$37,$B3,Upgrades!$E$2:$E$37,"<="&$D3) -> 6 | N3: =MIN(1,INDEX(Türme!$U$2:$U$7,MATCH($A3,Türme!$A$2:$A$7,0)) + SUMIFS(Upgrades!$AE$2:$AE$37,Upgrades!$A$2:$A$37,$A3,Upgrades!$B$2:$B$37,$B3,Upgrades!$E$2:$E$37,"<="&$D3)) -> 0 | O3: =INDEX(Türme!$V$2:$V$7,MATCH($A3,Türme!$A$2:$A$7,0)) + SUMIFS(Upgrades!$AF$2:$AF$37,Upgrades!$A$2:$A$37,$A3,Upgrades!$B$2:$B$37,$B3,Upgrades!$E$2:$E$37,"<="&$D3) -> 0 | P3: =MIN(1,INDEX(Türme!$W$2:$W$7,MATCH($A3,Türme!$A$2:$A$7,0)) + SUMIFS(Upgrades!$AG$2:$AG$37,Upgrades!$A$2:$A$37,$A3,Upgrades!$B$2:$B$37,$B3,Upgrades!$E$2:$E$37,"<="&$D3)) -> 0 | Q3: =MIN(1,INDEX(Türme!$X$2:$X$7,MATCH($A3,Türme!$A$2:$A$7,0)) + SUMIFS(Upgrades!$AH$2:$AH$37,Upgrades!$A$2:$A$37,$A3,Upgrades!$B$2:$B$37,$B3,Upgrades!$E$2:$E$37,"<="&$D3)) -> 0
A4: Glibberwerfer | B4: 0 | C4: Glibberwerfer - Hüpfer | D4: 3 | E4: =INDEX(Türme!$N$2:$N$7,MATCH($A4,Türme!$A$2:$A$7,0)) + SUMIFS(Upgrades!$J$2:$J$37,Upgrades!$A$2:$A$37,$A4,Upgrades!$B$2:$B$37,$B4,Upgrades!$E$2:$E$37,"<="&$D4) + SUMIFS(Upgrades!$W$2:$W$37,Upgrades!$A$2:$A$37,$A4,Upgrades!$B$2:$B$37,$B4,Upgrades!$E$2:$E$37,"<="&$D4) -> 11 | F4: =MAX(0.1,INDEX(Türme!$O$2:$O$7,MATCH($A4,Türme!$A$2:$A$7,0)) - SUMIFS(Upgrades!$M$2:$M$37,Upgrades!$A$2:$A$37,$A4,Upgrades!$B$2:$B$37,$B4,Upgrades!$E$2:$E$37,"<="&$D4) - SUMIFS(Upgrades!$Y$2:$Y$37,Upgrades!$A$2:$A$37,$A4,Upgrades!$B$2:$B$37,$B4,Upgrades!$E$2:$E$37,"<="&$D4)) -> 1.45 | G4: =E4/F4 -> 7.5862069 | H4: =INDEX(Türme!$L$2:$L$7,MATCH($A4,Türme!$A$2:$A$7,0)) + SUMIFS(Upgrades!$K$2:$K$37,Upgrades!$A$2:$A$37,$A4,Upgrades!$B$2:$B$37,$B4,Upgrades!$E$2:$E$37,"<="&$D4) + SUMIFS(Upgrades!$X$2:$X$37,Upgrades!$A$2:$A$37,$A4,Upgrades!$B$2:$B$37,$B4,Upgrades!$E$2:$E$37,"<="&$D4) -> 6.8 | I4: =INDEX(Türme!$G$2:$G$7,MATCH($A4,Türme!$A$2:$A$7,0)) + SUMIFS(Upgrades!$O$2:$O$37,Upgrades!$A$2:$A$37,$A4,Upgrades!$B$2:$B$37,$B4,Upgrades!$E$2:$E$37,"<="&$D4) + SUMIFS(Upgrades!$U$2:$U$37,Upgrades!$A$2:$A$37,$A4,Upgrades!$B$2:$B$37,$B4,Upgrades!$E$2:$E$37,"<="&$D4) -> 160 | J4: =INDEX(Türme!$I$2:$I$7,MATCH($A4,Türme!$A$2:$A$7,0)) + SUMIFS(Upgrades!$Z$2:$Z$37,Upgrades!$A$2:$A$37,$A4,Upgrades!$B$2:$B$37,$B4,Upgrades!$E$2:$E$37,"<="&$D4) -> 5 | K4: =INDEX(Türme!$J$2:$J$7,MATCH($A4,Türme!$A$2:$A$7,0)) + SUMIFS(Upgrades!$AA$2:$AA$37,Upgrades!$A$2:$A$37,$A4,Upgrades!$B$2:$B$37,$B4,Upgrades!$E$2:$E$37,"<="&$D4) -> 0 | L4: =MIN(1,INDEX(Türme!$R$2:$R$7,MATCH($A4,Türme!$A$2:$A$7,0)) + SUMIFS(Upgrades!$AB$2:$AB$37,Upgrades!$A$2:$A$37,$A4,Upgrades!$B$2:$B$37,$B4,Upgrades!$E$2:$E$37,"<="&$D4)) -> 0.1 | M4: =INDEX(Türme!$T$2:$T$7,MATCH($A4,Türme!$A$2:$A$7,0)) + SUMIFS(Upgrades!$AD$2:$AD$37,Upgrades!$A$2:$A$37,$A4,Upgrades!$B$2:$B$37,$B4,Upgrades!$E$2:$E$37,"<="&$D4) -> 14 | N4: =MIN(1,INDEX(Türme!$U$2:$U$7,MATCH($A4,Türme!$A$2:$A$7,0)) + SUMIFS(Upgrades!$AE$2:$AE$37,Upgrades!$A$2:$A$37,$A4,Upgrades!$B$2:$B$37,$B4,Upgrades!$E$2:$E$37,"<="&$D4)) -> 0 | O4: =INDEX(Türme!$V$2:$V$7,MATCH($A4,Türme!$A$2:$A$7,0)) + SUMIFS(Upgrades!$AF$2:$AF$37,Upgrades!$A$2:$A$37,$A4,Upgrades!$B$2:$B$37,$B4,Upgrades!$E$2:$E$37,"<="&$D4) -> 0 | P4: =MIN(1,INDEX(Türme!$W$2:$W$7,MATCH($A4,Türme!$A$2:$A$7,0)) + SUMIFS(Upgrades!$AG$2:$AG$37,Upgrades!$A$2:$A$37,$A4,Upgrades!$B$2:$B$37,$B4,Upgrades!$E$2:$E$37,"<="&$D4)) -> 0 | Q4: =MIN(1,INDEX(Türme!$X$2:$X$7,MATCH($A4,Türme!$A$2:$A$7,0)) + SUMIFS(Upgrades!$AH$2:$AH$37,Upgrades!$A$2:$A$37,$A4,Upgrades!$B$2:$B$37,$B4,Upgrades!$E$2:$E$37,"<="&$D4)) -> 0
A5: Glibberwerfer | B5: 1 | C5: Glibberwerfer - Klebrig | D5: 2 | E5: =INDEX(Türme!$N$2:$N$7,MATCH($A5,Türme!$A$2:$A$7,0)) + SUMIFS(Upgrades!$J$2:$J$37,Upgrades!$A$2:$A$37,$A5,Upgrades!$B$2:$B$37,$B5,Upgrades!$E$2:$E$37,"<="&$D5) + SUMIFS(Upgrades!$W$2:$W$37,Upgrades!$A$2:$A$37,$A5,Upgrades!$B$2:$B$37,$B5,Upgrades!$E$2:$E$37,"<="&$D5) -> 8 | F5: =MAX(0.1,INDEX(Türme!$O$2:$O$7,MATCH($A5,Türme!$A$2:$A$7,0)) - SUMIFS(Upgrades!$M$2:$M$37,Upgrades!$A$2:$A$37,$A5,Upgrades!$B$2:$B$37,$B5,Upgrades!$E$2:$E$37,"<="&$D5) - SUMIFS(Upgrades!$Y$2:$Y$37,Upgrades!$A$2:$A$37,$A5,Upgrades!$B$2:$B$37,$B5,Upgrades!$E$2:$E$37,"<="&$D5)) -> 1.5 | G5: =E5/F5 -> 5.3333333 | H5: =INDEX(Türme!$L$2:$L$7,MATCH($A5,Türme!$A$2:$A$7,0)) + SUMIFS(Upgrades!$K$2:$K$37,Upgrades!$A$2:$A$37,$A5,Upgrades!$B$2:$B$37,$B5,Upgrades!$E$2:$E$37,"<="&$D5) + SUMIFS(Upgrades!$X$2:$X$37,Upgrades!$A$2:$A$37,$A5,Upgrades!$B$2:$B$37,$B5,Upgrades!$E$2:$E$37,"<="&$D5) -> 6.3 | I5: =INDEX(Türme!$G$2:$G$7,MATCH($A5,Türme!$A$2:$A$7,0)) + SUMIFS(Upgrades!$O$2:$O$37,Upgrades!$A$2:$A$37,$A5,Upgrades!$B$2:$B$37,$B5,Upgrades!$E$2:$E$37,"<="&$D5) + SUMIFS(Upgrades!$U$2:$U$37,Upgrades!$A$2:$A$37,$A5,Upgrades!$B$2:$B$37,$B5,Upgrades!$E$2:$E$37,"<="&$D5) -> 125 | J5: =INDEX(Türme!$I$2:$I$7,MATCH($A5,Türme!$A$2:$A$7,0)) + SUMIFS(Upgrades!$Z$2:$Z$37,Upgrades!$A$2:$A$37,$A5,Upgrades!$B$2:$B$37,$B5,Upgrades!$E$2:$E$37,"<="&$D5) -> 5 | K5: =INDEX(Türme!$J$2:$J$7,MATCH($A5,Türme!$A$2:$A$7,0)) + SUMIFS(Upgrades!$AA$2:$AA$37,Upgrades!$A$2:$A$37,$A5,Upgrades!$B$2:$B$37,$B5,Upgrades!$E$2:$E$37,"<="&$D5) -> 0 | L5: =MIN(1,INDEX(Türme!$R$2:$R$7,MATCH($A5,Türme!$A$2:$A$7,0)) + SUMIFS(Upgrades!$AB$2:$AB$37,Upgrades!$A$2:$A$37,$A5,Upgrades!$B$2:$B$37,$B5,Upgrades!$E$2:$E$37,"<="&$D5)) -> 0 | M5: =INDEX(Türme!$T$2:$T$7,MATCH($A5,Türme!$A$2:$A$7,0)) + SUMIFS(Upgrades!$AD$2:$AD$37,Upgrades!$A$2:$A$37,$A5,Upgrades!$B$2:$B$37,$B5,Upgrades!$E$2:$E$37,"<="&$D5) -> 0 | N5: =MIN(1,INDEX(Türme!$U$2:$U$7,MATCH($A5,Türme!$A$2:$A$7,0)) + SUMIFS(Upgrades!$AE$2:$AE$37,Upgrades!$A$2:$A$37,$A5,Upgrades!$B$2:$B$37,$B5,Upgrades!$E$2:$E$37,"<="&$D5)) -> 0.1 | O5: =INDEX(Türme!$V$2:$V$7,MATCH($A5,Türme!$A$2:$A$7,0)) + SUMIFS(Upgrades!$AF$2:$AF$37,Upgrades!$A$2:$A$37,$A5,Upgrades!$B$2:$B$37,$B5,Upgrades!$E$2:$E$37,"<="&$D5) -> 0 | P5: =MIN(1,INDEX(Türme!$W$2:$W$7,MATCH($A5,Türme!$A$2:$A$7,0)) + SUMIFS(Upgrades!$AG$2:$AG$37,Upgrades!$A$2:$A$37,$A5,Upgrades!$B$2:$B$37,$B5,Upgrades!$E$2:$E$37,"<="&$D5)) -> 0 | Q5: =MIN(1,INDEX(Türme!$X$2:$X$7,MATCH($A5,Türme!$A$2:$A$7,0)) + SUMIFS(Upgrades!$AH$2:$AH$37,Upgrades!$A$2:$A$37,$A5,Upgrades!$B$2:$B$37,$B5,Upgrades!$E$2:$E$37,"<="&$D5)) -> 0
A6: Glibberwerfer | B6: 1 | C6: Glibberwerfer - Klebrig | D6: 3 | E6: =INDEX(Türme!$N$2:$N$7,MATCH($A6,Türme!$A$2:$A$7,0)) + SUMIFS(Upgrades!$J$2:$J$37,Upgrades!$A$2:$A$37,$A6,Upgrades!$B$2:$B$37,$B6,Upgrades!$E$2:$E$37,"<="&$D6) + SUMIFS(Upgrades!$W$2:$W$37,Upgrades!$A$2:$A$37,$A6,Upgrades!$B$2:$B$37,$B6,Upgrades!$E$2:$E$37,"<="&$D6) -> 9 | F6: =MAX(0.1,INDEX(Türme!$O$2:$O$7,MATCH($A6,Türme!$A$2:$A$7,0)) - SUMIFS(Upgrades!$M$2:$M$37,Upgrades!$A$2:$A$37,$A6,Upgrades!$B$2:$B$37,$B6,Upgrades!$E$2:$E$37,"<="&$D6) - SUMIFS(Upgrades!$Y$2:$Y$37,Upgrades!$A$2:$A$37,$A6,Upgrades!$B$2:$B$37,$B6,Upgrades!$E$2:$E$37,"<="&$D6)) -> 1.4 | G6: =E6/F6 -> 6.4285714 | H6: =INDEX(Türme!$L$2:$L$7,MATCH($A6,Türme!$A$2:$A$7,0)) + SUMIFS(Upgrades!$K$2:$K$37,Upgrades!$A$2:$A$37,$A6,Upgrades!$B$2:$B$37,$B6,Upgrades!$E$2:$E$37,"<="&$D6) + SUMIFS(Upgrades!$X$2:$X$37,Upgrades!$A$2:$A$37,$A6,Upgrades!$B$2:$B$37,$B6,Upgrades!$E$2:$E$37,"<="&$D6) -> 6.3 | I6: =INDEX(Türme!$G$2:$G$7,MATCH($A6,Türme!$A$2:$A$7,0)) + SUMIFS(Upgrades!$O$2:$O$37,Upgrades!$A$2:$A$37,$A6,Upgrades!$B$2:$B$37,$B6,Upgrades!$E$2:$E$37,"<="&$D6) + SUMIFS(Upgrades!$U$2:$U$37,Upgrades!$A$2:$A$37,$A6,Upgrades!$B$2:$B$37,$B6,Upgrades!$E$2:$E$37,"<="&$D6) -> 150 | J6: =INDEX(Türme!$I$2:$I$7,MATCH($A6,Türme!$A$2:$A$7,0)) + SUMIFS(Upgrades!$Z$2:$Z$37,Upgrades!$A$2:$A$37,$A6,Upgrades!$B$2:$B$37,$B6,Upgrades!$E$2:$E$37,"<="&$D6) -> 5 | K6: =INDEX(Türme!$J$2:$J$7,MATCH($A6,Türme!$A$2:$A$7,0)) + SUMIFS(Upgrades!$AA$2:$AA$37,Upgrades!$A$2:$A$37,$A6,Upgrades!$B$2:$B$37,$B6,Upgrades!$E$2:$E$37,"<="&$D6) -> 0 | L6: =MIN(1,INDEX(Türme!$R$2:$R$7,MATCH($A6,Türme!$A$2:$A$7,0)) + SUMIFS(Upgrades!$AB$2:$AB$37,Upgrades!$A$2:$A$37,$A6,Upgrades!$B$2:$B$37,$B6,Upgrades!$E$2:$E$37,"<="&$D6)) -> 0 | M6: =INDEX(Türme!$T$2:$T$7,MATCH($A6,Türme!$A$2:$A$7,0)) + SUMIFS(Upgrades!$AD$2:$AD$37,Upgrades!$A$2:$A$37,$A6,Upgrades!$B$2:$B$37,$B6,Upgrades!$E$2:$E$37,"<="&$D6) -> 4 | N6: =MIN(1,INDEX(Türme!$U$2:$U$7,MATCH($A6,Türme!$A$2:$A$7,0)) + SUMIFS(Upgrades!$AE$2:$AE$37,Upgrades!$A$2:$A$37,$A6,Upgrades!$B$2:$B$37,$B6,Upgrades!$E$2:$E$37,"<="&$D6)) -> 0.2 | O6: =INDEX(Türme!$V$2:$V$7,MATCH($A6,Türme!$A$2:$A$7,0)) + SUMIFS(Upgrades!$AF$2:$AF$37,Upgrades!$A$2:$A$37,$A6,Upgrades!$B$2:$B$37,$B6,Upgrades!$E$2:$E$37,"<="&$D6) -> 0 | P6: =MIN(1,INDEX(Türme!$W$2:$W$7,MATCH($A6,Türme!$A$2:$A$7,0)) + SUMIFS(Upgrades!$AG$2:$AG$37,Upgrades!$A$2:$A$37,$A6,Upgrades!$B$2:$B$37,$B6,Upgrades!$E$2:$E$37,"<="&$D6)) -> 0 | Q6: =MIN(1,INDEX(Türme!$X$2:$X$7,MATCH($A6,Türme!$A$2:$A$7,0)) + SUMIFS(Upgrades!$AH$2:$AH$37,Upgrades!$A$2:$A$37,$A6,Upgrades!$B$2:$B$37,$B6,Upgrades!$E$2:$E$37,"<="&$D6)) -> 0
A7: Glibberwerfer | B7: 2 | C7: Glibberwerfer - Pudding | D7: 2 | E7: =INDEX(Türme!$N$2:$N$7,MATCH($A7,Türme!$A$2:$A$7,0)) + SUMIFS(Upgrades!$J$2:$J$37,Upgrades!$A$2:$A$37,$A7,Upgrades!$B$2:$B$37,$B7,Upgrades!$E$2:$E$37,"<="&$D7) + SUMIFS(Upgrades!$W$2:$W$37,Upgrades!$A$2:$A$37,$A7,Upgrades!$B$2:$B$37,$B7,Upgrades!$E$2:$E$37,"<="&$D7) -> 8 | F7: =MAX(0.1,INDEX(Türme!$O$2:$O$7,MATCH($A7,Türme!$A$2:$A$7,0)) - SUMIFS(Upgrades!$M$2:$M$37,Upgrades!$A$2:$A$37,$A7,Upgrades!$B$2:$B$37,$B7,Upgrades!$E$2:$E$37,"<="&$D7) - SUMIFS(Upgrades!$Y$2:$Y$37,Upgrades!$A$2:$A$37,$A7,Upgrades!$B$2:$B$37,$B7,Upgrades!$E$2:$E$37,"<="&$D7)) -> 1.6 | G7: =E7/F7 -> 5 | H7: =INDEX(Türme!$L$2:$L$7,MATCH($A7,Türme!$A$2:$A$7,0)) + SUMIFS(Upgrades!$K$2:$K$37,Upgrades!$A$2:$A$37,$A7,Upgrades!$B$2:$B$37,$B7,Upgrades!$E$2:$E$37,"<="&$D7) + SUMIFS(Upgrades!$X$2:$X$37,Upgrades!$A$2:$A$37,$A7,Upgrades!$B$2:$B$37,$B7,Upgrades!$E$2:$E$37,"<="&$D7) -> 6 | I7: =INDEX(Türme!$G$2:$G$7,MATCH($A7,Türme!$A$2:$A$7,0)) + SUMIFS(Upgrades!$O$2:$O$37,Upgrades!$A$2:$A$37,$A7,Upgrades!$B$2:$B$37,$B7,Upgrades!$E$2:$E$37,"<="&$D7) + SUMIFS(Upgrades!$U$2:$U$37,Upgrades!$A$2:$A$37,$A7,Upgrades!$B$2:$B$37,$B7,Upgrades!$E$2:$E$37,"<="&$D7) -> 190 | J7: =INDEX(Türme!$I$2:$I$7,MATCH($A7,Türme!$A$2:$A$7,0)) + SUMIFS(Upgrades!$Z$2:$Z$37,Upgrades!$A$2:$A$37,$A7,Upgrades!$B$2:$B$37,$B7,Upgrades!$E$2:$E$37,"<="&$D7) -> 30 | K7: =INDEX(Türme!$J$2:$J$7,MATCH($A7,Türme!$A$2:$A$7,0)) + SUMIFS(Upgrades!$AA$2:$AA$37,Upgrades!$A$2:$A$37,$A7,Upgrades!$B$2:$B$37,$B7,Upgrades!$E$2:$E$37,"<="&$D7) -> 15 | L7: =MIN(1,INDEX(Türme!$R$2:$R$7,MATCH($A7,Türme!$A$2:$A$7,0)) + SUMIFS(Upgrades!$AB$2:$AB$37,Upgrades!$A$2:$A$37,$A7,Upgrades!$B$2:$B$37,$B7,Upgrades!$E$2:$E$37,"<="&$D7)) -> 0 | M7: =INDEX(Türme!$T$2:$T$7,MATCH($A7,Türme!$A$2:$A$7,0)) + SUMIFS(Upgrades!$AD$2:$AD$37,Upgrades!$A$2:$A$37,$A7,Upgrades!$B$2:$B$37,$B7,Upgrades!$E$2:$E$37,"<="&$D7) -> 0 | N7: =MIN(1,INDEX(Türme!$U$2:$U$7,MATCH($A7,Türme!$A$2:$A$7,0)) + SUMIFS(Upgrades!$AE$2:$AE$37,Upgrades!$A$2:$A$37,$A7,Upgrades!$B$2:$B$37,$B7,Upgrades!$E$2:$E$37,"<="&$D7)) -> 0 | O7: =INDEX(Türme!$V$2:$V$7,MATCH($A7,Türme!$A$2:$A$7,0)) + SUMIFS(Upgrades!$AF$2:$AF$37,Upgrades!$A$2:$A$37,$A7,Upgrades!$B$2:$B$37,$B7,Upgrades!$E$2:$E$37,"<="&$D7) -> 0 | P7: =MIN(1,INDEX(Türme!$W$2:$W$7,MATCH($A7,Türme!$A$2:$A$7,0)) + SUMIFS(Upgrades!$AG$2:$AG$37,Upgrades!$A$2:$A$37,$A7,Upgrades!$B$2:$B$37,$B7,Upgrades!$E$2:$E$37,"<="&$D7)) -> 0 | Q7: =MIN(1,INDEX(Türme!$X$2:$X$7,MATCH($A7,Türme!$A$2:$A$7,0)) + SUMIFS(Upgrades!$AH$2:$AH$37,Upgrades!$A$2:$A$37,$A7,Upgrades!$B$2:$B$37,$B7,Upgrades!$E$2:$E$37,"<="&$D7)) -> 0.06
A8: Glibberwerfer | B8: 2 | C8: Glibberwerfer - Pudding | D8: 3 | E8: =INDEX(Türme!$N$2:$N$7,MATCH($A8,Türme!$A$2:$A$7,0)) + SUMIFS(Upgrades!$J$2:$J$37,Upgrades!$A$2:$A$37,$A8,Upgrades!$B$2:$B$37,$B8,Upgrades!$E$2:$E$37,"<="&$D8) + SUMIFS(Upgrades!$W$2:$W$37,Upgrades!$A$2:$A$37,$A8,Upgrades!$B$2:$B$37,$B8,Upgrades!$E$2:$E$37,"<="&$D8) -> 9 | F8: =MAX(0.1,INDEX(Türme!$O$2:$O$7,MATCH($A8,Türme!$A$2:$A$7,0)) - SUMIFS(Upgrades!$M$2:$M$37,Upgrades!$A$2:$A$37,$A8,Upgrades!$B$2:$B$37,$B8,Upgrades!$E$2:$E$37,"<="&$D8) - SUMIFS(Upgrades!$Y$2:$Y$37,Upgrades!$A$2:$A$37,$A8,Upgrades!$B$2:$B$37,$B8,Upgrades!$E$2:$E$37,"<="&$D8)) -> 1.6 | G8: =E8/F8 -> 5.625 | H8: =INDEX(Türme!$L$2:$L$7,MATCH($A8,Türme!$A$2:$A$7,0)) + SUMIFS(Upgrades!$K$2:$K$37,Upgrades!$A$2:$A$37,$A8,Upgrades!$B$2:$B$37,$B8,Upgrades!$E$2:$E$37,"<="&$D8) + SUMIFS(Upgrades!$X$2:$X$37,Upgrades!$A$2:$A$37,$A8,Upgrades!$B$2:$B$37,$B8,Upgrades!$E$2:$E$37,"<="&$D8) -> 6 | I8: =INDEX(Türme!$G$2:$G$7,MATCH($A8,Türme!$A$2:$A$7,0)) + SUMIFS(Upgrades!$O$2:$O$37,Upgrades!$A$2:$A$37,$A8,Upgrades!$B$2:$B$37,$B8,Upgrades!$E$2:$E$37,"<="&$D8) + SUMIFS(Upgrades!$U$2:$U$37,Upgrades!$A$2:$A$37,$A8,Upgrades!$B$2:$B$37,$B8,Upgrades!$E$2:$E$37,"<="&$D8) -> 350 | J8: =INDEX(Türme!$I$2:$I$7,MATCH($A8,Türme!$A$2:$A$7,0)) + SUMIFS(Upgrades!$Z$2:$Z$37,Upgrades!$A$2:$A$37,$A8,Upgrades!$B$2:$B$37,$B8,Upgrades!$E$2:$E$37,"<="&$D8) -> 70 | K8: =INDEX(Türme!$J$2:$J$7,MATCH($A8,Türme!$A$2:$A$7,0)) + SUMIFS(Upgrades!$AA$2:$AA$37,Upgrades!$A$2:$A$37,$A8,Upgrades!$B$2:$B$37,$B8,Upgrades!$E$2:$E$37,"<="&$D8) -> 45 | L8: =MIN(1,INDEX(Türme!$R$2:$R$7,MATCH($A8,Türme!$A$2:$A$7,0)) + SUMIFS(Upgrades!$AB$2:$AB$37,Upgrades!$A$2:$A$37,$A8,Upgrades!$B$2:$B$37,$B8,Upgrades!$E$2:$E$37,"<="&$D8)) -> 0 | M8: =INDEX(Türme!$T$2:$T$7,MATCH($A8,Türme!$A$2:$A$7,0)) + SUMIFS(Upgrades!$AD$2:$AD$37,Upgrades!$A$2:$A$37,$A8,Upgrades!$B$2:$B$37,$B8,Upgrades!$E$2:$E$37,"<="&$D8) -> 0 | N8: =MIN(1,INDEX(Türme!$U$2:$U$7,MATCH($A8,Türme!$A$2:$A$7,0)) + SUMIFS(Upgrades!$AE$2:$AE$37,Upgrades!$A$2:$A$37,$A8,Upgrades!$B$2:$B$37,$B8,Upgrades!$E$2:$E$37,"<="&$D8)) -> 0 | O8: =INDEX(Türme!$V$2:$V$7,MATCH($A8,Türme!$A$2:$A$7,0)) + SUMIFS(Upgrades!$AF$2:$AF$37,Upgrades!$A$2:$A$37,$A8,Upgrades!$B$2:$B$37,$B8,Upgrades!$E$2:$E$37,"<="&$D8) -> 0 | P8: =MIN(1,INDEX(Türme!$W$2:$W$7,MATCH($A8,Türme!$A$2:$A$7,0)) + SUMIFS(Upgrades!$AG$2:$AG$37,Upgrades!$A$2:$A$37,$A8,Upgrades!$B$2:$B$37,$B8,Upgrades!$E$2:$E$37,"<="&$D8)) -> 0 | Q8: =MIN(1,INDEX(Türme!$X$2:$X$7,MATCH($A8,Türme!$A$2:$A$7,0)) + SUMIFS(Upgrades!$AH$2:$AH$37,Upgrades!$A$2:$A$37,$A8,Upgrades!$B$2:$B$37,$B8,Upgrades!$E$2:$E$37,"<="&$D8)) -> 0.12
A9: Säuretümpel | C9: Basis | D9: 1 | E9: =INDEX(Türme!$N$2:$N$7,MATCH($A9,Türme!$A$2:$A$7,0)) -> 5 | F9: =MAX(0.1,INDEX(Türme!$O$2:$O$7,MATCH($A9,Türme!$A$2:$A$7,0))) -> 2.2 | G9: =E9/F9 -> 2.2727273 | H9: =INDEX(Türme!$L$2:$L$7,MATCH($A9,Türme!$A$2:$A$7,0)) -> 5.5 | I9: =INDEX(Türme!$G$2:$G$7,MATCH($A9,Türme!$A$2:$A$7,0)) -> 100 | J9: =INDEX(Türme!$I$2:$I$7,MATCH($A9,Türme!$A$2:$A$7,0)) -> 0 | K9: =INDEX(Türme!$J$2:$J$7,MATCH($A9,Türme!$A$2:$A$7,0)) -> 5 | L9: =MIN(1,INDEX(Türme!$R$2:$R$7,MATCH($A9,Türme!$A$2:$A$7,0))) -> 0 | M9: =INDEX(Türme!$T$2:$T$7,MATCH($A9,Türme!$A$2:$A$7,0)) -> 0 | N9: =MIN(1,INDEX(Türme!$U$2:$U$7,MATCH($A9,Türme!$A$2:$A$7,0))) -> 0 | O9: =INDEX(Türme!$V$2:$V$7,MATCH($A9,Türme!$A$2:$A$7,0)) -> 0 | P9: =MIN(1,INDEX(Türme!$W$2:$W$7,MATCH($A9,Türme!$A$2:$A$7,0))) -> 0 | Q9: =MIN(1,INDEX(Türme!$X$2:$X$7,MATCH($A9,Türme!$A$2:$A$7,0))) -> 0
A10: Säuretümpel | B10: 0 | C10: Säuretümpel - Ätzer | D10: 2 | E10: =INDEX(Türme!$N$2:$N$7,MATCH($A10,Türme!$A$2:$A$7,0)) + SUMIFS(Upgrades!$J$2:$J$37,Upgrades!$A$2:$A$37,$A10,Upgrades!$B$2:$B$37,$B10,Upgrades!$E$2:$E$37,"<="&$D10) + SUMIFS(Upgrades!$W$2:$W$37,Upgrades!$A$2:$A$37,$A10,Upgrades!$B$2:$B$37,$B10,Upgrades!$E$2:$E$37,"<="&$D10) -> 6 | F10: =MAX(0.1,INDEX(Türme!$O$2:$O$7,MATCH($A10,Türme!$A$2:$A$7,0)) - SUMIFS(Upgrades!$M$2:$M$37,Upgrades!$A$2:$A$37,$A10,Upgrades!$B$2:$B$37,$B10,Upgrades!$E$2:$E$37,"<="&$D10) - SUMIFS(Upgrades!$Y$2:$Y$37,Upgrades!$A$2:$A$37,$A10,Upgrades!$B$2:$B$37,$B10,Upgrades!$E$2:$E$37,"<="&$D10)) -> 2.2 | G10: =E10/F10 -> 2.7272727 | H10: =INDEX(Türme!$L$2:$L$7,MATCH($A10,Türme!$A$2:$A$7,0)) + SUMIFS(Upgrades!$K$2:$K$37,Upgrades!$A$2:$A$37,$A10,Upgrades!$B$2:$B$37,$B10,Upgrades!$E$2:$E$37,"<="&$D10) + SUMIFS(Upgrades!$X$2:$X$37,Upgrades!$A$2:$A$37,$A10,Upgrades!$B$2:$B$37,$B10,Upgrades!$E$2:$E$37,"<="&$D10) -> 5.5 | I10: =INDEX(Türme!$G$2:$G$7,MATCH($A10,Türme!$A$2:$A$7,0)) + SUMIFS(Upgrades!$O$2:$O$37,Upgrades!$A$2:$A$37,$A10,Upgrades!$B$2:$B$37,$B10,Upgrades!$E$2:$E$37,"<="&$D10) + SUMIFS(Upgrades!$U$2:$U$37,Upgrades!$A$2:$A$37,$A10,Upgrades!$B$2:$B$37,$B10,Upgrades!$E$2:$E$37,"<="&$D10) -> 100 | J10: =INDEX(Türme!$I$2:$I$7,MATCH($A10,Türme!$A$2:$A$7,0)) + SUMIFS(Upgrades!$Z$2:$Z$37,Upgrades!$A$2:$A$37,$A10,Upgrades!$B$2:$B$37,$B10,Upgrades!$E$2:$E$37,"<="&$D10) -> 0 | K10: =INDEX(Türme!$J$2:$J$7,MATCH($A10,Türme!$A$2:$A$7,0)) + SUMIFS(Upgrades!$AA$2:$AA$37,Upgrades!$A$2:$A$37,$A10,Upgrades!$B$2:$B$37,$B10,Upgrades!$E$2:$E$37,"<="&$D10) -> 5 | L10: =MIN(1,INDEX(Türme!$R$2:$R$7,MATCH($A10,Türme!$A$2:$A$7,0)) + SUMIFS(Upgrades!$AB$2:$AB$37,Upgrades!$A$2:$A$37,$A10,Upgrades!$B$2:$B$37,$B10,Upgrades!$E$2:$E$37,"<="&$D10)) -> 0 | M10: =INDEX(Türme!$T$2:$T$7,MATCH($A10,Türme!$A$2:$A$7,0)) + SUMIFS(Upgrades!$AD$2:$AD$37,Upgrades!$A$2:$A$37,$A10,Upgrades!$B$2:$B$37,$B10,Upgrades!$E$2:$E$37,"<="&$D10) -> 0 | N10: =MIN(1,INDEX(Türme!$U$2:$U$7,MATCH($A10,Türme!$A$2:$A$7,0)) + SUMIFS(Upgrades!$AE$2:$AE$37,Upgrades!$A$2:$A$37,$A10,Upgrades!$B$2:$B$37,$B10,Upgrades!$E$2:$E$37,"<="&$D10)) -> 0 | O10: =INDEX(Türme!$V$2:$V$7,MATCH($A10,Türme!$A$2:$A$7,0)) + SUMIFS(Upgrades!$AF$2:$AF$37,Upgrades!$A$2:$A$37,$A10,Upgrades!$B$2:$B$37,$B10,Upgrades!$E$2:$E$37,"<="&$D10) -> 5 | P10: =MIN(1,INDEX(Türme!$W$2:$W$7,MATCH($A10,Türme!$A$2:$A$7,0)) + SUMIFS(Upgrades!$AG$2:$AG$37,Upgrades!$A$2:$A$37,$A10,Upgrades!$B$2:$B$37,$B10,Upgrades!$E$2:$E$37,"<="&$D10)) -> 0 | Q10: =MIN(1,INDEX(Türme!$X$2:$X$7,MATCH($A10,Türme!$A$2:$A$7,0)) + SUMIFS(Upgrades!$AH$2:$AH$37,Upgrades!$A$2:$A$37,$A10,Upgrades!$B$2:$B$37,$B10,Upgrades!$E$2:$E$37,"<="&$D10)) -> 0
A11: Säuretümpel | B11: 0 | C11: Säuretümpel - Ätzer | D11: 3 | E11: =INDEX(Türme!$N$2:$N$7,MATCH($A11,Türme!$A$2:$A$7,0)) + SUMIFS(Upgrades!$J$2:$J$37,Upgrades!$A$2:$A$37,$A11,Upgrades!$B$2:$B$37,$B11,Upgrades!$E$2:$E$37,"<="&$D11) + SUMIFS(Upgrades!$W$2:$W$37,Upgrades!$A$2:$A$37,$A11,Upgrades!$B$2:$B$37,$B11,Upgrades!$E$2:$E$37,"<="&$D11) -> 8 | F11: =MAX(0.1,INDEX(Türme!$O$2:$O$7,MATCH($A11,Türme!$A$2:$A$7,0)) - SUMIFS(Upgrades!$M$2:$M$37,Upgrades!$A$2:$A$37,$A11,Upgrades!$B$2:$B$37,$B11,Upgrades!$E$2:$E$37,"<="&$D11) - SUMIFS(Upgrades!$Y$2:$Y$37,Upgrades!$A$2:$A$37,$A11,Upgrades!$B$2:$B$37,$B11,Upgrades!$E$2:$E$37,"<="&$D11)) -> 2.2 | G11: =E11/F11 -> 3.6363636 | H11: =INDEX(Türme!$L$2:$L$7,MATCH($A11,Türme!$A$2:$A$7,0)) + SUMIFS(Upgrades!$K$2:$K$37,Upgrades!$A$2:$A$37,$A11,Upgrades!$B$2:$B$37,$B11,Upgrades!$E$2:$E$37,"<="&$D11) + SUMIFS(Upgrades!$X$2:$X$37,Upgrades!$A$2:$A$37,$A11,Upgrades!$B$2:$B$37,$B11,Upgrades!$E$2:$E$37,"<="&$D11) -> 5.8 | I11: =INDEX(Türme!$G$2:$G$7,MATCH($A11,Türme!$A$2:$A$7,0)) + SUMIFS(Upgrades!$O$2:$O$37,Upgrades!$A$2:$A$37,$A11,Upgrades!$B$2:$B$37,$B11,Upgrades!$E$2:$E$37,"<="&$D11) + SUMIFS(Upgrades!$U$2:$U$37,Upgrades!$A$2:$A$37,$A11,Upgrades!$B$2:$B$37,$B11,Upgrades!$E$2:$E$37,"<="&$D11) -> 100 | J11: =INDEX(Türme!$I$2:$I$7,MATCH($A11,Türme!$A$2:$A$7,0)) + SUMIFS(Upgrades!$Z$2:$Z$37,Upgrades!$A$2:$A$37,$A11,Upgrades!$B$2:$B$37,$B11,Upgrades!$E$2:$E$37,"<="&$D11) -> 0 | K11: =INDEX(Türme!$J$2:$J$7,MATCH($A11,Türme!$A$2:$A$7,0)) + SUMIFS(Upgrades!$AA$2:$AA$37,Upgrades!$A$2:$A$37,$A11,Upgrades!$B$2:$B$37,$B11,Upgrades!$E$2:$E$37,"<="&$D11) -> 5 | L11: =MIN(1,INDEX(Türme!$R$2:$R$7,MATCH($A11,Türme!$A$2:$A$7,0)) + SUMIFS(Upgrades!$AB$2:$AB$37,Upgrades!$A$2:$A$37,$A11,Upgrades!$B$2:$B$37,$B11,Upgrades!$E$2:$E$37,"<="&$D11)) -> 0 | M11: =INDEX(Türme!$T$2:$T$7,MATCH($A11,Türme!$A$2:$A$7,0)) + SUMIFS(Upgrades!$AD$2:$AD$37,Upgrades!$A$2:$A$37,$A11,Upgrades!$B$2:$B$37,$B11,Upgrades!$E$2:$E$37,"<="&$D11) -> 0 | N11: =MIN(1,INDEX(Türme!$U$2:$U$7,MATCH($A11,Türme!$A$2:$A$7,0)) + SUMIFS(Upgrades!$AE$2:$AE$37,Upgrades!$A$2:$A$37,$A11,Upgrades!$B$2:$B$37,$B11,Upgrades!$E$2:$E$37,"<="&$D11)) -> 0 | O11: =INDEX(Türme!$V$2:$V$7,MATCH($A11,Türme!$A$2:$A$7,0)) + SUMIFS(Upgrades!$AF$2:$AF$37,Upgrades!$A$2:$A$37,$A11,Upgrades!$B$2:$B$37,$B11,Upgrades!$E$2:$E$37,"<="&$D11) -> 10 | P11: =MIN(1,INDEX(Türme!$W$2:$W$7,MATCH($A11,Türme!$A$2:$A$7,0)) + SUMIFS(Upgrades!$AG$2:$AG$37,Upgrades!$A$2:$A$37,$A11,Upgrades!$B$2:$B$37,$B11,Upgrades!$E$2:$E$37,"<="&$D11)) -> 0.15 | Q11: =MIN(1,INDEX(Türme!$X$2:$X$7,MATCH($A11,Türme!$A$2:$A$7,0)) + SUMIFS(Upgrades!$AH$2:$AH$37,Upgrades!$A$2:$A$37,$A11,Upgrades!$B$2:$B$37,$B11,Upgrades!$E$2:$E$37,"<="&$D11)) -> 0
A12: Säuretümpel | B12: 1 | C12: Säuretümpel - Verdauer | D12: 2 | E12: =INDEX(Türme!$N$2:$N$7,MATCH($A12,Türme!$A$2:$A$7,0)) + SUMIFS(Upgrades!$J$2:$J$37,Upgrades!$A$2:$A$37,$A12,Upgrades!$B$2:$B$37,$B12,Upgrades!$E$2:$E$37,"<="&$D12) + SUMIFS(Upgrades!$W$2:$W$37,Upgrades!$A$2:$A$37,$A12,Upgrades!$B$2:$B$37,$B12,Upgrades!$E$2:$E$37,"<="&$D12) -> 5 | F12: =MAX(0.1,INDEX(Türme!$O$2:$O$7,MATCH($A12,Türme!$A$2:$A$7,0)) - SUMIFS(Upgrades!$M$2:$M$37,Upgrades!$A$2:$A$37,$A12,Upgrades!$B$2:$B$37,$B12,Upgrades!$E$2:$E$37,"<="&$D12) - SUMIFS(Upgrades!$Y$2:$Y$37,Upgrades!$A$2:$A$37,$A12,Upgrades!$B$2:$B$37,$B12,Upgrades!$E$2:$E$37,"<="&$D12)) -> 2 | G12: =E12/F12 -> 2.5 | H12: =INDEX(Türme!$L$2:$L$7,MATCH($A12,Türme!$A$2:$A$7,0)) + SUMIFS(Upgrades!$K$2:$K$37,Upgrades!$A$2:$A$37,$A12,Upgrades!$B$2:$B$37,$B12,Upgrades!$E$2:$E$37,"<="&$D12) + SUMIFS(Upgrades!$X$2:$X$37,Upgrades!$A$2:$A$37,$A12,Upgrades!$B$2:$B$37,$B12,Upgrades!$E$2:$E$37,"<="&$D12) -> 5.5 | I12: =INDEX(Türme!$G$2:$G$7,MATCH($A12,Türme!$A$2:$A$7,0)) + SUMIFS(Upgrades!$O$2:$O$37,Upgrades!$A$2:$A$37,$A12,Upgrades!$B$2:$B$37,$B12,Upgrades!$E$2:$E$37,"<="&$D12) + SUMIFS(Upgrades!$U$2:$U$37,Upgrades!$A$2:$A$37,$A12,Upgrades!$B$2:$B$37,$B12,Upgrades!$E$2:$E$37,"<="&$D12) -> 100 | J12: =INDEX(Türme!$I$2:$I$7,MATCH($A12,Türme!$A$2:$A$7,0)) + SUMIFS(Upgrades!$Z$2:$Z$37,Upgrades!$A$2:$A$37,$A12,Upgrades!$B$2:$B$37,$B12,Upgrades!$E$2:$E$37,"<="&$D12) -> 0 | K12: =INDEX(Türme!$J$2:$J$7,MATCH($A12,Türme!$A$2:$A$7,0)) + SUMIFS(Upgrades!$AA$2:$AA$37,Upgrades!$A$2:$A$37,$A12,Upgrades!$B$2:$B$37,$B12,Upgrades!$E$2:$E$37,"<="&$D12) -> 5 | L12: =MIN(1,INDEX(Türme!$R$2:$R$7,MATCH($A12,Türme!$A$2:$A$7,0)) + SUMIFS(Upgrades!$AB$2:$AB$37,Upgrades!$A$2:$A$37,$A12,Upgrades!$B$2:$B$37,$B12,Upgrades!$E$2:$E$37,"<="&$D12)) -> 0 | M12: =INDEX(Türme!$T$2:$T$7,MATCH($A12,Türme!$A$2:$A$7,0)) + SUMIFS(Upgrades!$AD$2:$AD$37,Upgrades!$A$2:$A$37,$A12,Upgrades!$B$2:$B$37,$B12,Upgrades!$E$2:$E$37,"<="&$D12) -> 0 | N12: =MIN(1,INDEX(Türme!$U$2:$U$7,MATCH($A12,Türme!$A$2:$A$7,0)) + SUMIFS(Upgrades!$AE$2:$AE$37,Upgrades!$A$2:$A$37,$A12,Upgrades!$B$2:$B$37,$B12,Upgrades!$E$2:$E$37,"<="&$D12)) -> 0 | O12: =INDEX(Türme!$V$2:$V$7,MATCH($A12,Türme!$A$2:$A$7,0)) + SUMIFS(Upgrades!$AF$2:$AF$37,Upgrades!$A$2:$A$37,$A12,Upgrades!$B$2:$B$37,$B12,Upgrades!$E$2:$E$37,"<="&$D12) -> 0 | P12: =MIN(1,INDEX(Türme!$W$2:$W$7,MATCH($A12,Türme!$A$2:$A$7,0)) + SUMIFS(Upgrades!$AG$2:$AG$37,Upgrades!$A$2:$A$37,$A12,Upgrades!$B$2:$B$37,$B12,Upgrades!$E$2:$E$37,"<="&$D12)) -> 0 | Q12: =MIN(1,INDEX(Türme!$X$2:$X$7,MATCH($A12,Türme!$A$2:$A$7,0)) + SUMIFS(Upgrades!$AH$2:$AH$37,Upgrades!$A$2:$A$37,$A12,Upgrades!$B$2:$B$37,$B12,Upgrades!$E$2:$E$37,"<="&$D12)) -> 0
A13: Säuretümpel | B13: 1 | C13: Säuretümpel - Verdauer | D13: 3 | E13: =INDEX(Türme!$N$2:$N$7,MATCH($A13,Türme!$A$2:$A$7,0)) + SUMIFS(Upgrades!$J$2:$J$37,Upgrades!$A$2:$A$37,$A13,Upgrades!$B$2:$B$37,$B13,Upgrades!$E$2:$E$37,"<="&$D13) + SUMIFS(Upgrades!$W$2:$W$37,Upgrades!$A$2:$A$37,$A13,Upgrades!$B$2:$B$37,$B13,Upgrades!$E$2:$E$37,"<="&$D13) -> 6 | F13: =MAX(0.1,INDEX(Türme!$O$2:$O$7,MATCH($A13,Türme!$A$2:$A$7,0)) - SUMIFS(Upgrades!$M$2:$M$37,Upgrades!$A$2:$A$37,$A13,Upgrades!$B$2:$B$37,$B13,Upgrades!$E$2:$E$37,"<="&$D13) - SUMIFS(Upgrades!$Y$2:$Y$37,Upgrades!$A$2:$A$37,$A13,Upgrades!$B$2:$B$37,$B13,Upgrades!$E$2:$E$37,"<="&$D13)) -> 1.8 | G13: =E13/F13 -> 3.3333333 | H13: =INDEX(Türme!$L$2:$L$7,MATCH($A13,Türme!$A$2:$A$7,0)) + SUMIFS(Upgrades!$K$2:$K$37,Upgrades!$A$2:$A$37,$A13,Upgrades!$B$2:$B$37,$B13,Upgrades!$E$2:$E$37,"<="&$D13) + SUMIFS(Upgrades!$X$2:$X$37,Upgrades!$A$2:$A$37,$A13,Upgrades!$B$2:$B$37,$B13,Upgrades!$E$2:$E$37,"<="&$D13) -> 5.5 | I13: =INDEX(Türme!$G$2:$G$7,MATCH($A13,Türme!$A$2:$A$7,0)) + SUMIFS(Upgrades!$O$2:$O$37,Upgrades!$A$2:$A$37,$A13,Upgrades!$B$2:$B$37,$B13,Upgrades!$E$2:$E$37,"<="&$D13) + SUMIFS(Upgrades!$U$2:$U$37,Upgrades!$A$2:$A$37,$A13,Upgrades!$B$2:$B$37,$B13,Upgrades!$E$2:$E$37,"<="&$D13) -> 100 | J13: =INDEX(Türme!$I$2:$I$7,MATCH($A13,Türme!$A$2:$A$7,0)) + SUMIFS(Upgrades!$Z$2:$Z$37,Upgrades!$A$2:$A$37,$A13,Upgrades!$B$2:$B$37,$B13,Upgrades!$E$2:$E$37,"<="&$D13) -> 0 | K13: =INDEX(Türme!$J$2:$J$7,MATCH($A13,Türme!$A$2:$A$7,0)) + SUMIFS(Upgrades!$AA$2:$AA$37,Upgrades!$A$2:$A$37,$A13,Upgrades!$B$2:$B$37,$B13,Upgrades!$E$2:$E$37,"<="&$D13) -> 5 | L13: =MIN(1,INDEX(Türme!$R$2:$R$7,MATCH($A13,Türme!$A$2:$A$7,0)) + SUMIFS(Upgrades!$AB$2:$AB$37,Upgrades!$A$2:$A$37,$A13,Upgrades!$B$2:$B$37,$B13,Upgrades!$E$2:$E$37,"<="&$D13)) -> 0 | M13: =INDEX(Türme!$T$2:$T$7,MATCH($A13,Türme!$A$2:$A$7,0)) + SUMIFS(Upgrades!$AD$2:$AD$37,Upgrades!$A$2:$A$37,$A13,Upgrades!$B$2:$B$37,$B13,Upgrades!$E$2:$E$37,"<="&$D13) -> 0 | N13: =MIN(1,INDEX(Türme!$U$2:$U$7,MATCH($A13,Türme!$A$2:$A$7,0)) + SUMIFS(Upgrades!$AE$2:$AE$37,Upgrades!$A$2:$A$37,$A13,Upgrades!$B$2:$B$37,$B13,Upgrades!$E$2:$E$37,"<="&$D13)) -> 0 | O13: =INDEX(Türme!$V$2:$V$7,MATCH($A13,Türme!$A$2:$A$7,0)) + SUMIFS(Upgrades!$AF$2:$AF$37,Upgrades!$A$2:$A$37,$A13,Upgrades!$B$2:$B$37,$B13,Upgrades!$E$2:$E$37,"<="&$D13) -> 0 | P13: =MIN(1,INDEX(Türme!$W$2:$W$7,MATCH($A13,Türme!$A$2:$A$7,0)) + SUMIFS(Upgrades!$AG$2:$AG$37,Upgrades!$A$2:$A$37,$A13,Upgrades!$B$2:$B$37,$B13,Upgrades!$E$2:$E$37,"<="&$D13)) -> 0.15 | Q13: =MIN(1,INDEX(Türme!$X$2:$X$7,MATCH($A13,Türme!$A$2:$A$7,0)) + SUMIFS(Upgrades!$AH$2:$AH$37,Upgrades!$A$2:$A$37,$A13,Upgrades!$B$2:$B$37,$B13,Upgrades!$E$2:$E$37,"<="&$D13)) -> 0
